Workbook
Name EsfuerzodelPlan: #REF!
Name log_HorasTrabajadas: #REF!
Name log_PorcentajeTareas: #REF!
Name MiembrosEquipo: #REF!
Name log_NombresMiembroEquipo: #REF!
Name log_SemanaTrabajada: #REF!
Name log_CodigosActividad: #REF!
Name SemanadelPlan: #REF!
Name PersonasdelPlan: #REF!
Name FasesProceso: #REF!
Name CodigosActividad: #REF!
Name TareasdelPlan: #REF!

Sheet Ayuda
A1: Instrucciones para generar el informe de valor ganado
A2: Pasos
A3: 0 | B3: Introducir el nombre del proyecto, el nombre de la compañía o su logo en la hoja de informe
A4: 1 | B4: Dar de alta los nombres de los miembros del equipo y sus abreviaturas en la hoja de Equipo. Además hay que renombrar las hojas existentes. Si hay menos miembros poner un miembro ficticio.Asegurrarse que el nombre de las hojas corresponden coon las abreviaturas del equipo.
A5: 2 | B5: Dar de alta la lista de Tareas del proyecto en la hoja de Tareas. La hoja de tareas contiene un ejemplo que hay que adaptar según el plan de proyecto de cada equipo. Ahorra se tiene codificado un maximo de 200 tareas.
A6: 3 | B6: Introducir las horas planificadas para cada tarea (PV, a partir de la columna N ) según el plan de proyecto en cada una de las hojas de los miembros del equipo
A7: 4 | B7: Una vez planificado el proyecto hay que ir introduciendo los esfuerzo real de cada tarea (AC , a partir de columna C en cada hoja de cada miembro) de cada para cada uno de los miembros del equipo
A8: 5 | B8: Tambien hay que introducir el avance de cada tarea en la hoja EV, en la hoja aparecen sombreadas en color azul las celdas donde se han dedicado horas de trabajo
A9: 6 | B9: Tambien se pueden hacer anotaciones en el campo Resumen de la hoja de informe para registrar las decisiones que afectan al proyecto
A10: 7 | B10: En la hoja de informe indicar la fecha del informe y la semana para la que se quiere realizar el informe (ajustar las semanas a las semanas del ciclo, p. ej. Ciclo 1, 7 semanas)
A18: Version
A19: H | B19: Actualizada la formula del calculo del TBC: Ampliando la suma hasta la semana 8, en la version anterior solo sumaba hasta la 7

Sheet Informe
A1: BEERSP | M1: BeerSP
A3: Informe del Analisis de Valor Ganado
B5: Preparado por: | C5: Laura Herández
B6: Fecha informe: | C6: 45964
B9: Para el periodo: | C9: 8 | D9: ← Puedes cambiar la semana del informe
A12: Resumen:
B13: [Usa este espacio para escribir un breve resumen o aquellas anotaciones que quieras destacar]
A22: Planned Value (PV) o Budgeted Cost of Work Scheduled (BCWS) | D22: S1 | E22: S2 | F22: S3 | G22: S4 | H22: S5 | I22: S6 | J22: S7 | K22: S8 | P22: ← Puedes cambiar las etiquetas para los periodos (ej. Week 1/2/3, Semana 1/2/3, etc.)
C23: Coste Total Presupuestado | D23: =PV!D7 -> 9.4 | E23: =PV!E7 -> 8.5 | F23: =PV!F7 -> 14.2 | G23: =PV!G7 -> 12 | H23: =PV!H7 -> 8.7 | I23: =PV!I7 -> 7.6 | J23: =PV!J7 -> 15.8 | K23: =PV!K7 -> 11.3 | P23: solo hace falta editar los valores de las celdas azules
C24: Valor Planificado Acumulado | D24: =IF(D23="","",D23) -> 9.4 | E24: =IF(E23="",D24,D24+E23) -> 17.9 | F24: =IF(F23="",E24,E24+F23) -> 32.1 | G24: =IF(G23="",F24,F24+G23) -> 44.1 | H24: =IF(H23="",G24,G24+H23) -> 52.8 | I24: =IF(I23="",H24,H24+I23) -> 60.4 | J24: =IF(J23="",I24,I24+J23) -> 76.2 | K24: =IF(K23="",J24,J24+K23) -> 87.5
C25: Presupuesto Inicial | D25: =MAX(PV!D8:K8) -> 87.5
A27: Coste Actual y Valor Ganado
C28: Coste Real Acumulado (AC) | D28: =IF($C$9>=COLUMN(D$22)-3,AC!D7,NA()) -> 7.6 | E28: =IF($C$9>=COLUMN(E$22)-3,AC!E7,NA()) -> 13.1 | F28: =IF($C$9>=COLUMN(F$22)-3,AC!F7,NA()) -> 28.3 | G28: =IF($C$9>=COLUMN(G$22)-3,AC!G7,NA()) -> 42.1 | H28: =IF($C$9>=COLUMN(H$22)-3,AC!H7,NA()) -> 51.8 | I28: =IF($C$9>=COLUMN(I$22)-3,AC!I7,NA()) -> 58.7 | J28: =IF($C$9>=COLUMN(J$22)-3,AC!J7,NA()) -> 69.2 | K28: =IF($C$9>=COLUMN(K$22)-3,AC!K7,NA()) -> 79.3
C29: Valor Ganado Acumulado(EV) | D29: =IF($C$9>=COLUMN(D$22)-3,EV!D7,NA()) -> 9.4 | E29: =IF($C$9>=COLUMN(E$22)-3,EV!E7,NA()) -> 17.1 | F29: =IF($C$9>=COLUMN(F$22)-3,EV!F7,NA()) -> 36.65 | G29: =IF($C$9>=COLUMN(G$22)-3,EV!G7,NA()) -> 43.1 | H29: =IF($C$9>=COLUMN(H$22)-3,EV!H7,NA()) -> 52.8 | I29: =IF($C$9>=COLUMN(I$22)-3,EV!I7,NA()) -> 60.4 | J29: =IF($C$9>=COLUMN(J$22)-3,EV!J7,NA()) -> 74 | K29: =IF($C$9>=COLUMN(K$22)-3,EV!K7,NA()) -> 87.5
C30: Coste real proyecto | D30: =MAX(AC!D7:K7) -> 79.3
A32: Metricas de rendimiento del Proyecto
C33: Cost Variance (CV = EV - AC) | D33: =IF(OR(ISERROR(D28),ISERROR(D29))," - ",D29-D28) -> 1.8 | E33: =IF(OR(ISERROR(E28),ISERROR(E29))," - ",E29-E28) -> 4 | F33: =IF(OR(ISERROR(F28),ISERROR(F29))," - ",F29-F28) -> 8.35 | G33: =IF(OR(ISERROR(G28),ISERROR(G29))," - ",G29-G28) -> 1 | H33: =IF(OR(ISERROR(H28),ISERROR(H29))," - ",H29-H28) -> 1 | I33: =IF(OR(ISERROR(I28),ISERROR(I29))," - ",I29-I28) -> 1.7 | J33: =IF(OR(ISERROR(J28),ISERROR(J29))," - ",J29-J28) -> 4.8 | K33: =IF(OR(ISERROR(K28),ISERROR(K29))," - ",K29-K28) -> 8.2
C34: Schedule Variance (SV = EV - PV) | D34: =IF(OR(ISERROR(D24),ISERROR(D29))," - ",D29-D24) -> 0 | E34: =IF(OR(ISERROR(E24),ISERROR(E29))," - ",E29-E24) -> -0.8 | F34: =IF(OR(ISERROR(F24),ISERROR(F29))," - ",F29-F24) -> 4.55 | G34: =IF(OR(ISERROR(G24),ISERROR(G29))," - ",G29-G24) -> -1 | H34: =IF(OR(ISERROR(H24),ISERROR(H29))," - ",H29-H24) -> 0 | I34: =IF(OR(ISERROR(I24),ISERROR(I29))," - ",I29-I24) -> 0 | J34: =IF(OR(ISERROR(J24),ISERROR(J29))," - ",J29-J24) -> -2.2 | K34: =IF(OR(ISERROR(K24),ISERROR(K29))," - ",K29-K24) -> 0
C35: Cost Performance Index (CPI = EV/AC) | D35: =IF(OR(ISERROR(D28),ISERROR(D29))," - ",D29/D28) -> 1.2368421 | E35: =IF(OR(ISERROR(E28),ISERROR(E29))," - ",E29/E28) -> 1.3053435 | F35: =IF(OR(ISERROR(F28),ISERROR(F29))," - ",F29/F28) -> 1.295053 | G35: =IF(OR(ISERROR(G28),ISERROR(G29))," - ",G29/G28) -> 1.023753 | H35: =IF(OR(ISERROR(H28),ISERROR(H29))," - ",H29/H28) -> 1.019305 | I35: =IF(OR(ISERROR(I28),ISERROR(I29))," - ",I29/I28) -> 1.0289608 | J35: =IF(OR(ISERROR(J28),ISERROR(J29))," - ",J29/J28) -> 1.0693642 | K35: =IF(OR(ISERROR(K28),ISERROR(K29))," - ",K29/K28) -> 1.1034048
C36: Schedule Performance Index (SPI = EV/PV) | D36: =IF(OR(ISERROR(D24),ISERROR(D29))," - ",D29/D24) -> 1 | E36: =IF(OR(ISERROR(E24),ISERROR(E29))," - ",E29/E24) -> 0.95530726 | F36: =IF(OR(ISERROR(F24),ISERROR(F29))," - ",F29/F24) -> 1.1417445 | G36: =IF(OR(ISERROR(G24),ISERROR(G29))," - ",G29/G24) -> 0.97732426 | H36: =IF(OR(ISERROR(H24),ISERROR(H29))," - ",H29/H24) -> 1 | I36: =IF(OR(ISERROR(I24),ISERROR(I29))," - ",I29/I24) -> 1 | J36: =IF(OR(ISERROR(J24),ISERROR(J29))," - ",J29/J24) -> 0.97112861 | K36: =IF(OR(ISERROR(K24),ISERROR(K29))," - ",K29/K24) -> 1
C37: Estimated Cost at Completion (EAC) | D37: =IF(AND(ISERROR(D28),ISERROR(D29))," - ",$D$25/D35) -> 70.744681 | E37: =IF(AND(ISERROR(E28),ISERROR(E29))," - ",$D$25/E35) -> 67.032164 | F37: =IF(AND(ISERROR(F28),ISERROR(F29))," - ",$D$25/F35) -> 67.564802 | G37: =IF(AND(ISERROR(G28),ISERROR(G29))," - ",$D$25/G35) -> 85.469838 | H37: =IF(AND(ISERROR(H28),ISERROR(H29))," - ",$D$25/H35) -> 85.842803 | I37: =IF(AND(ISERROR(I28),ISERROR(I29))," - ",$D$25/I35) -> 85.037252 | J37: =IF(AND(ISERROR(J28),ISERROR(J29))," - ",$D$25/J35) -> 81.824324 | K37: =IF(AND(ISERROR(K28),ISERROR(K29))," - ",$D$25/K35) -> 79.3
B40: Ratios productividad Real del Ciclo
D41: Coste Real Acumulado (AC) | E41: =D30 -> 79.3 | H41: Coste Real Acumulado (AC) | I41: =D30 -> 79.3
D42: Puntos de Funcion Ciclo (PF) | E42: 83 | H42: Lineas de Código (LOC) | I42: 2028
D43: Ratio de productividad | E43: =IF(E42=0,"Falta PF",E41/E42) -> 0.95542169 | F43: horas/PF | H43: Ratio de productividad | I43: =IF(I42=0,"Falta LOC",I41/I42) -> 0.039102564 | J43: horas/LOC

Sheet EV
A1: Hoja de Valor Ganado
B2: Completa el porcentaje de progreso que tiene cada tarea
B3: Asegurate que los nombres son los mismos
B4: Introduce el % de avance para cada tarea, de esa manera se calcula el valor ganado
B5: Cuando una tarea ha alcanzado el 100% en la semanas posteriores sigue intrroduciendo el 100% | M5: ← Las celdas con sombreado azul significa que se ha trabajado horas
A7: Valor Ganado Acumulado(EV) | D7: =SUMPRODUCT($C$10:$C1000,D$10:D1000) -> 9.4 | E7: =SUMPRODUCT($C$10:$C1000,E$10:E1000) -> 17.1 | F7: =SUMPRODUCT($C$10:$C1000,F$10:F1000) -> 36.65 | G7: =SUMPRODUCT($C$10:$C1000,G$10:G1000) -> 43.1 | H7: =SUMPRODUCT($C$10:$C1000,H$10:H1000) -> 52.8 | I7: =SUMPRODUCT($C$10:$C1000,I$10:I1000) -> 60.4 | J7: =SUMPRODUCT($C$10:$C1000,J$10:J1000) -> 74 | K7: =SUMPRODUCT($C$10:$C1000,K$10:K1000) -> 87.5
B9: Nombre Tarea | C9: TBC | D9: =Informe!D22 -> S1 | E9: =Informe!E22 -> S2 | F9: =Informe!F22 -> S3 | G9: =Informe!G22 -> S4 | H9: =Informe!H22 -> S5 | I9: =Informe!I22 -> S6 | J9: =Informe!J22 -> S7 | K9: =Informe!K22 -> S8
B10: =IF(ISBLANK(Tareas!B6)," - ",Tareas!B6) -> 1. Reunión 1 | C10: =PV!C10 -> 4.5 | D10: 1 | E10: =IF(D10="","",MAX($D10:D10)) -> 1 | F10: =IF(E10="","",MAX($D10:E10)) -> 1 | G10: =IF(F10="","",MAX($D10:F10)) -> 1 | H10: =IF(G10="","",MAX($D10:G10)) -> 1 | I10: =IF(H10="","",MAX($D10:H10)) -> 1 | J10: =IF(I10="","",MAX($D10:I10)) -> 1 | K10: =IF(J10="","",MAX($D10:J10)) -> 1
B11: =IF(ISBLANK(Tareas!B7)," - ",Tareas!B7) -> 2. Asignación de roles | C11: =PV!C11 -> 0.9 | D11: 1 | E11: =IF(D11="","",MAX($D11:D11)) -> 1 | F11: =IF(E11="","",MAX($D11:E11)) -> 1 | G11: =IF(F11="","",MAX($D11:F11)) -> 1 | H11: =IF(G11="","",MAX($D11:G11)) -> 1 | I11: =IF(H11="","",MAX($D11:H11)) -> 1 | J11: =IF(I11="","",MAX($D11:I11)) -> 1 | K11: =IF(J11="","",MAX($D11:J11)) -> 1
B12: =IF(ISBLANK(Tareas!B8)," - ",Tareas!B8) -> 3. Definición del estándar de documentación | C12: =PV!C12 -> 1.2 | D12: 1 | E12: =IF(D12="","",MAX($D12:D12)) -> 1 | F12: =IF(E12="","",MAX($D12:E12)) -> 1 | G12: =IF(F12="","",MAX($D12:F12)) -> 1 | H12: =IF(G12="","",MAX($D12:G12)) -> 1 | I12: =IF(H12="","",MAX($D12:H12)) -> 1 | J12: =IF(I12="","",MAX($D12:I12)) -> 1 | K12: =IF(J12="","",MAX($D12:J12)) -> 1
B13: =IF(ISBLANK(Tareas!B9)," - ",Tareas!B9) -> 4. Definición del estándar de proceso | C13: =PV!C13 -> 2.2 | D13: 1 | E13: =IF(D13="","",MAX($D13:D13)) -> 1 | F13: =IF(E13="","",MAX($D13:E13)) -> 1 | G13: =IF(F13="","",MAX($D13:F13)) -> 1 | H13: =IF(G13="","",MAX($D13:G13)) -> 1 | I13: =IF(H13="","",MAX($D13:H13)) -> 1 | J13: =IF(I13="","",MAX($D13:I13)) -> 1 | K13: =IF(J13="","",MAX($D13:J13)) -> 1
B14: =IF(ISBLANK(Tareas!B10)," - ",Tareas!B10) -> 5. Definición del entorno de desarrollo | C14: =PV!C14 -> 0.6 | D14: 1 | E14: =IF(D14="","",MAX($D14:D14)) -> 1 | F14: =IF(E14="","",MAX($D14:E14)) -> 1 | G14: =IF(F14="","",MAX($D14:F14)) -> 1 | H14: =IF(G14="","",MAX($D14:G14)) -> 1 | I14: =IF(H14="","",MAX($D14:H14)) -> 1 | J14: =IF(I14="","",MAX($D14:I14)) -> 1 | K14: =IF(J14="","",MAX($D14:J14)) -> 1
B15: =IF(ISBLANK(Tareas!B11)," - ",Tareas!B11) -> 6. Reunión 2 | C15: =PV!C15 -> 4.5 | D15: 0 | E15: 1 | F15: =IF(E15="","",MAX($D15:E15)) -> 1 | G15: =IF(F15="","",MAX($D15:F15)) -> 1 | H15: =IF(G15="","",MAX($D15:G15)) -> 1 | I15: =IF(H15="","",MAX($D15:H15)) -> 1 | J15: =IF(I15="","",MAX($D15:I15)) -> 1 | K15: =IF(J15="","",MAX($D15:J15)) -> 1
B16: =IF(ISBLANK(Tareas!B12)," - ",Tareas!B12) -> 7. Realización del análisis de requisitos (ERS) | C16: =PV!C16 -> 4 | D16: 0 | E16: 0.8 | F16: 1 | G16: =IF(F16="","",MAX($D16:F16)) -> 1 | H16: =IF(G16="","",MAX($D16:G16)) -> 1 | I16: =IF(H16="","",MAX($D16:H16)) -> 1 | J16: =IF(I16="","",MAX($D16:I16)) -> 1 | K16: =IF(J16="","",MAX($D16:J16)) -> 1
B17: =IF(ISBLANK(Tareas!B13)," - ",Tareas!B13) -> 8. Reunión 3 | C17: =PV!C17 -> 4.5 | D17: 0 | E17: =IF(D17="","",MAX($D17:D17)) -> 0 | F17: 1 | G17: =IF(F17="","",MAX($D17:F17)) -> 1 | H17: =IF(G17="","",MAX($D17:G17)) -> 1 | I17: =IF(H17="","",MAX($D17:H17)) -> 1 | J17: =IF(I17="","",MAX($D17:I17)) -> 1 | K17: =IF(J17="","",MAX($D17:J17)) -> 1
B18: =IF(ISBLANK(Tareas!B14)," - ",Tareas!B14) -> 9. Revisión del análisis de requisitos | C18: =PV!C18 -> 1.4 | D18: 0 | E18: =IF(D18="","",MAX($D18:D18)) -> 0 | F18: 1 | G18: =IF(F18="","",MAX($D18:F18)) -> 1 | H18: =IF(G18="","",MAX($D18:G18)) -> 1 | I18: =IF(H18="","",MAX($D18:H18)) -> 1 | J18: =IF(I18="","",MAX($D18:I18)) -> 1 | K18: =IF(J18="","",MAX($D18:J18)) -> 1
B19: =IF(ISBLANK(Tareas!B15)," - ",Tareas!B15) -> 10. Disposición del ERS en la línea base (GCS) | C19: =PV!C19 -> 0.3 | D19: 0 | E19: =IF(D19="","",MAX($D19:D19)) -> 0 | F19: 1 | G19: =IF(F19="","",MAX($D19:F19)) -> 1 | H19: =IF(G19="","",MAX($D19:G19)) -> 1 | I19: =IF(H19="","",MAX($D19:H19)) -> 1 | J19: =IF(I19="","",MAX($D19:I19)) -> 1 | K19: =IF(J19="","",MAX($D19:J19)) -> 1
B20: =IF(ISBLANK(Tareas!B16)," - ",Tareas!B16) -> 11. Definición del plan para el ciclo de vida 1 | C20: =PV!C20 -> 1.5 | D20: 0 | E20: =IF(D20="","",MAX($D20:D20)) -> 0 | F20: 1 | G20: =IF(F20="","",MAX($D20:F20)) -> 1 | H20: =IF(G20="","",MAX($D20:G20)) -> 1 | I20: =IF(H20="","",MAX($D20:H20)) -> 1 | J20: =IF(I20="","",MAX($D20:I20)) -> 1 | K20: =IF(J20="","",MAX($D20:J20)) -> 1
B21: =IF(ISBLANK(Tareas!B17)," - ",Tareas!B17) -> 12. Definición de los casos de uso y el modelo E/R | C21: =PV!C21 -> 2 | D21: 0 | E21: =IF(D21="","",MAX($D21:D21)) -> 0 | F21: 1 | G21: =IF(F21="","",MAX($D21:F21)) -> 1 | H21: =IF(G21="","",MAX($D21:G21)) -> 1 | I21: =IF(H21="","",MAX($D21:H21)) -> 1 | J21: =IF(I21="","",MAX($D21:I21)) -> 1 | K21: =IF(J21="","",MAX($D21:J21)) -> 1
B22: =IF(ISBLANK(Tareas!B18)," - ",Tareas!B18) -> 13. Definición del plan de calidad (PCAL) | C22: =PV!C22 -> 2 | D22: 0 | E22: =IF(D22="","",MAX($D22:D22)) -> 0 | F22: 1 | G22: =IF(F22="","",MAX($D22:F22)) -> 1 | H22: =IF(G22="","",MAX($D22:G22)) -> 1 | I22: =IF(H22="","",MAX($D22:H22)) -> 1 | J22: =IF(I22="","",MAX($D22:I22)) -> 1 | K22: =IF(J22="","",MAX($D22:J22)) -> 1
B23: =IF(ISBLANK(Tareas!B19)," - ",Tareas!B19) -> 14. Cálculo de los puntos de función | C23: =PV!C23 -> 1 | D23: 0 | E23: =IF(D23="","",MAX($D23:D23)) -> 0 | F23: 0.7 | G23: 0.9 | H23: 1 | I23: =IF(H23="","",MAX($D23:H23)) -> 1 | J23: =IF(I23="","",MAX($D23:I23)) -> 1 | K23: =IF(J23="","",MAX($D23:J23)) -> 1
B24: =IF(ISBLANK(Tareas!B20)," - ",Tareas!B20) -> 15. Realización del diagrama Gantt | C24: =PV!C24 -> 1.5 | D24: 0 | E24: =IF(D24="","",MAX($D24:D24)) -> 0 | F24: 0.9 | G24: 1 | H24: =IF(G24="","",MAX($D24:G24)) -> 1 | I24: =IF(H24="","",MAX($D24:H24)) -> 1 | J24: =IF(I24="","",MAX($D24:I24)) -> 1 | K24: =IF(J24="","",MAX($D24:J24)) -> 1
B25: =IF(ISBLANK(Tareas!B21)," - ",Tareas!B21) -> 16. Reunión 4 | C25: =PV!C25 -> 5 | D25: 0 | E25: =IF(D25="","",MAX($D25:D25)) -> 0 | F25: 1 | G25: =IF(F25="","",MAX($D25:F25)) -> 1 | H25: =IF(G25="","",MAX($D25:G25)) -> 1 | I25: =IF(H25="","",MAX($D25:H25)) -> 1 | J25: =IF(I25="","",MAX($D25:I25)) -> 1 | K25: =IF(J25="","",MAX($D25:J25)) -> 1
B26: =IF(ISBLANK(Tareas!B22)," - ",Tareas!B22) -> 17. Definición del plan de gestión de configuración software (GCS) | C26: =PV!C26 -> 3 | D26: 0 | E26: =IF(D26="","",MAX($D26:D26)) -> 0 | F26: =IF(E26="","",MAX($D26:E26)) -> 0 | G26: 0.8 | H26: 1 | I26: =IF(H26="","",MAX($D26:H26)) -> 1 | J26: =IF(I26="","",MAX($D26:I26)) -> 1 | K26: =IF(J26="","",MAX($D26:J26)) -> 1
B27: =IF(ISBLANK(Tareas!B23)," - ",Tareas!B23) -> 18. Inicialización de la hoja de valor ganado (EVM) | C27: =PV!C27 -> 0.5 | D27: 0 | E27: =IF(D27="","",MAX($D27:D27)) -> 0 | F27: =IF(E27="","",MAX($D27:E27)) -> 0 | G27: 1 | H27: =IF(G27="","",MAX($D27:G27)) -> 1 | I27: =IF(H27="","",MAX($D27:H27)) -> 1 | J27: =IF(I27="","",MAX($D27:I27)) -> 1 | K27: =IF(J27="","",MAX($D27:J27)) -> 1
B28: =IF(ISBLANK(Tareas!B24)," - ",Tareas!B24) -> 19. Introducción de los datos en EVM | C28: =PV!C28 -> 2.5 | D28: 0 | E28: =IF(D28="","",MAX($D28:D28)) -> 0 | F28: =IF(E28="","",MAX($D28:E28)) -> 0 | G28: 1 | H28: =IF(G28="","",MAX($D28:G28)) -> 1 | I28: =IF(H28="","",MAX($D28:H28)) -> 1 | J28: =IF(I28="","",MAX($D28:I28)) -> 1 | K28: =IF(J28="","",MAX($D28:J28)) -> 1
B29: =IF(ISBLANK(Tareas!B25)," - ",Tareas!B25) -> 20. Definición del prototipo UI | C29: =PV!C29 -> 1 | D29: 0 | E29: =IF(D29="","",MAX($D29:D29)) -> 0 | F29: =IF(E29="","",MAX($D29:E29)) -> 0 | G29: 0.7 | H29: 1 | I29: =IF(H29="","",MAX($D29:H29)) -> 1 | J29: =IF(I29="","",MAX($D29:I29)) -> 1 | K29: =IF(J29="","",MAX($D29:J29)) -> 1
B30: =IF(ISBLANK(Tareas!B26)," - ",Tareas!B26) -> 21. Reunión 5 | C30: =PV!C30 -> 3.5 | D30: 0 | E30: =IF(D30="","",MAX($D30:D30)) -> 0 | F30: =IF(E30="","",MAX($D30:E30)) -> 0 | G30: =IF(F30="","",MAX($D30:F30)) -> 0 | H30: 1 | I30: =IF(H30="","",MAX($D30:H30)) -> 1 | J30: =IF(I30="","",MAX($D30:I30)) -> 1 | K30: =IF(J30="","",MAX($D30:J30)) -> 1
B31: =IF(ISBLANK(Tareas!B27)," - ",Tareas!B27) -> 22. Actualización de EVM | C31: =PV!C31 -> 0.5 | D31: 0 | E31: =IF(D31="","",MAX($D31:D31)) -> 0 | F31: =IF(E31="","",MAX($D31:E31)) -> 0 | G31: =IF(F31="","",MAX($D31:F31)) -> 0 | H31: 1 | I31: =IF(H31="","",MAX($D31:H31)) -> 1 | J31: =IF(I31="","",MAX($D31:I31)) -> 1 | K31: =IF(J31="","",MAX($D31:J31)) -> 1
B32: =IF(ISBLANK(Tareas!B28)," - ",Tareas!B28) -> 23. Revisión intermedia del diseño | C32: =PV!C32 -> 0.5 | D32: 0 | E32: =IF(D32="","",MAX($D32:D32)) -> 0 | F32: =IF(E32="","",MAX($D32:E32)) -> 0 | G32: =IF(F32="","",MAX($D32:F32)) -> 0 | H32: 1 | I32: =IF(H32="","",MAX($D32:H32)) -> 1 | J32: =IF(I32="","",MAX($D32:I32)) -> 1 | K32: =IF(J32="","",MAX($D32:J32)) -> 1
B33: =IF(ISBLANK(Tareas!B29)," - ",Tareas!B29) -> 24. Implementación de la persistencia y estructura de datos | C33: =PV!C33 -> 1 | D33: 0 | E33: =IF(D33="","",MAX($D33:D33)) -> 0 | F33: =IF(E33="","",MAX($D33:E33)) -> 0 | G33: =IF(F33="","",MAX($D33:F33)) -> 0 | H33: 1 | I33: =IF(H33="","",MAX($D33:H33)) -> 1 | J33: =IF(I33="","",MAX($D33:I33)) -> 1 | K33: =IF(J33="","",MAX($D33:J33)) -> 1
B34: =IF(ISBLANK(Tareas!B30)," - ",Tareas!B30) -> 25. Implementación de la gestión de usuarios | C34: =PV!C34 -> 1.4 | D34: 0 | E34: =IF(D34="","",MAX($D34:D34)) -> 0 | F34: =IF(E34="","",MAX($D34:E34)) -> 0 | G34: =IF(F34="","",MAX($D34:F34)) -> 0 | H34: 1 | I34: =IF(H34="","",MAX($D34:H34)) -> 1 | J34: =IF(I34="","",MAX($D34:I34)) -> 1 | K34: =IF(J34="","",MAX($D34:J34)) -> 1
B35: =IF(ISBLANK(Tareas!B31)," - ",Tareas!B31) -> 26. Implementación de la gestión de perfiles | C35: =PV!C35 -> 0.2 | D35: 0 | E35: =IF(D35="","",MAX($D35:D35)) -> 0 | F35: =IF(E35="","",MAX($D35:E35)) -> 0 | G35: =IF(F35="","",MAX($D35:F35)) -> 0 | H35: 1 | I35: =IF(H35="","",MAX($D35:H35)) -> 1 | J35: =IF(I35="","",MAX($D35:I35)) -> 1 | K35: =IF(J35="","",MAX($D35:J35)) -> 1
B36: =IF(ISBLANK(Tareas!B32)," - ",Tareas!B32) -> 27. Definición del diseño con objetos y pantallas finales | C36: =PV!C36 -> 0.5 | D36: 0 | E36: =IF(D36="","",MAX($D36:D36)) -> 0 | F36: =IF(E36="","",MAX($D36:E36)) -> 0 | G36: =IF(F36="","",MAX($D36:F36)) -> 0 | H36: 1 | I36: =IF(H36="","",MAX($D36:H36)) -> 1 | J36: =IF(I36="","",MAX($D36:I36)) -> 1 | K36: =IF(J36="","",MAX($D36:J36)) -> 1
B37: =IF(ISBLANK(Tareas!B33)," - ",Tareas!B33) -> 28. Revisión intermedia del código | C37: =PV!C37 -> 1.1 | D37: 0 | E37: =IF(D37="","",MAX($D37:D37)) -> 0 | F37: =IF(E37="","",MAX($D37:E37)) -> 0 | G37: =IF(F37="","",MAX($D37:F37)) -> 0 | H37: 1 | I37: =IF(H37="","",MAX($D37:H37)) -> 1 | J37: =IF(I37="","",MAX($D37:I37)) -> 1 | K37: =IF(J37="","",MAX($D37:J37)) -> 1
B38: =IF(ISBLANK(Tareas!B34)," - ",Tareas!B34) -> 29. Reunión 6 | C38: =PV!C38 -> 1.5 | D38: 0 | E38: =IF(D38="","",MAX($D38:D38)) -> 0 | F38: =IF(E38="","",MAX($D38:E38)) -> 0 | G38: =IF(F38="","",MAX($D38:F38)) -> 0 | H38: =IF(G38="","",MAX($D38:G38)) -> 0 | I38: 1 | J38: =IF(I38="","",MAX($D38:I38)) -> 1 | K38: =IF(J38="","",MAX($D38:J38)) -> 1
B39: =IF(ISBLANK(Tareas!B35)," - ",Tareas!B35) -> 30. Actualización de EVM | C39: =PV!C39 -> 0.5 | D39: 0 | E39: =IF(D39="","",MAX($D39:D39)) -> 0 | F39: =IF(E39="","",MAX($D39:E39)) -> 0 | G39: =IF(F39="","",MAX($D39:F39)) -> 0 | H39: =IF(G39="","",MAX($D39:G39)) -> 0 | I39: 1 | J39: =IF(I39="","",MAX($D39:I39)) -> 1 | K39: =IF(J39="","",MAX($D39:J39)) -> 1
B40: =IF(ISBLANK(Tareas!B36)," - ",Tareas!B36) -> 31. Implementación de la gestión de amistades | C40: =PV!C40 -> 1 | D40: 0 | E40: =IF(D40="","",MAX($D40:D40)) -> 0 | F40: =IF(E40="","",MAX($D40:E40)) -> 0 | G40: =IF(F40="","",MAX($D40:F40)) -> 0 | H40: =IF(G40="","",MAX($D40:G40)) -> 0 | I40: 1 | J40: =IF(I40="","",MAX($D40:I40)) -> 1 | K40: =IF(J40="","",MAX($D40:J40)) -> 1
B41: =IF(ISBLANK(Tareas!B37)," - ",Tareas!B37) -> 32. Implementación de la gestión de cervezas | C41: =PV!C41 -> 1 | D41: 0 | E41: =IF(D41="","",MAX($D41:D41)) -> 0 | F41: =IF(E41="","",MAX($D41:E41)) -> 0 | G41: =IF(F41="","",MAX($D41:F41)) -> 0 | H41: =IF(G41="","",MAX($D41:G41)) -> 0 | I41: 1 | J41: =IF(I41="","",MAX($D41:I41)) -> 1 | K41: =IF(J41="","",MAX($D41:J41)) -> 1
B42: =IF(ISBLANK(Tareas!B38)," - ",Tareas!B38) -> 33. Actualización de los planes de GCS y calidad | C42: =PV!C42 -> 0.3 | D42: 0 | E42: =IF(D42="","",MAX($D42:D42)) -> 0 | F42: =IF(E42="","",MAX($D42:E42)) -> 0 | G42: =IF(F42="","",MAX($D42:F42)) -> 0 | H42: =IF(G42="","",MAX($D42:G42)) -> 0 | I42: 1 | J42: =IF(I42="","",MAX($D42:I42)) -> 1 | K42: =IF(J42="","",MAX($D42:J42)) -> 1
...

Sheet Equipo
A1: Lista de personas y sus hojas
B3: Nombre | C3: Laura H | D3: Laura G | E3: Jonás R | F3: Valeria G | G3: Lucía M
B4: Acrónimo | C4: LH | D4: LG | E4: JR | F4: VG | G4: LM

Sheet LH
A1: Coste Reales y Costes Planificados
B2: En esta hoja se introducen los valores para cada tarea tanto reales de las horas trabajo del miembro de equipo asi como las horas que tuviera planificadas
B3: Asegurate que los nombres de las tareas son los mismos que el plan
A7: Horas Reales (AC) del Trabajo Planificado | L7: Horas Planificadas (PV)
B9: Nombre Tarea | C9: =Informe!D22 -> S1 | D9: =Informe!E22 -> S2 | E9: =Informe!F22 -> S3 | F9: =Informe!G22 -> S4 | G9: =Informe!H22 -> S5 | H9: =Informe!I22 -> S6 | I9: =Informe!J22 -> S7 | J9: =Informe!K22 -> S8 | M9: Nombre Tarea | N9: =Informe!D22 -> S1 | O9: =Informe!E22 -> S2 | P9: =Informe!F22 -> S3 | Q9: =Informe!G22 -> S4 | R9: =Informe!H22 -> S5 | S9: =Informe!I22 -> S6 | T9: =Informe!J22 -> S7 | U9: =Informe!K22 -> S8
B10: =IF(ISBLANK(Tareas!B6)," - ",Tareas!B6) -> 1. Reunión 1 | C10: 0.5 | D10: 0 | E10: 0 | F10: 0 | G10: 0 | H10: 0 | I10: 0 | J10: 0 | M10: =IF(ISBLANK(Tareas!B6)," - ",Tareas!B6) -> 1. Reunión 1 | N10: 1 | O10: 0 | P10: 0 | Q10: 0 | R10: 0 | S10: 0 | T10: 0 | U10: 0
B11: =IF(ISBLANK(Tareas!B7)," - ",Tareas!B7) -> 2. Asignación de roles | C11: 0.5 | D11: 0 | E11: 0 | F11: 0 | G11: 0 | H11: 0 | I11: 0 | J11: 0 | M11: =IF(ISBLANK(Tareas!B7)," - ",Tareas!B7) -> 2. Asignación de roles | N11: 0.3 | O11: 0 | P11: 0 | Q11: 0 | R11: 0 | S11: 0 | T11: 0 | U11: 0
B12: =IF(ISBLANK(Tareas!B8)," - ",Tareas!B8) -> 3. Definición del estándar de documentación | C12: 1 | D12: 0 | E12: 0 | F12: 0 | G12: 0 | H12: 0 | I12: 0 | J12: 0 | M12: =IF(ISBLANK(Tareas!B8)," - ",Tareas!B8) -> 3. Definición del estándar de documentación | N12: 0.5 | O12: 0 | P12: 0 | Q12: 0 | R12: 0 | S12: 0 | T12: 0 | U12: 0
B13: =IF(ISBLANK(Tareas!B9)," - ",Tareas!B9) -> 4. Definición del estándar de proceso | C13: 0 | D13: 0 | E13: 0 | F13: 0 | G13: 0 | H13: 0 | I13: 0 | J13: 0 | M13: =IF(ISBLANK(Tareas!B9)," - ",Tareas!B9) -> 4. Definición del estándar de proceso | N13: 0.3 | O13: 0 | P13: 0 | Q13: 0 | R13: 0 | S13: 0 | T13: 0 | U13: 0
B14: =IF(ISBLANK(Tareas!B10)," - ",Tareas!B10) -> 5. Definición del entorno de desarrollo | C14: 0.3 | D14: 0 | E14: 0 | F14: 0 | G14: 0 | H14: 0 | I14: 0 | J14: 0 | M14: =IF(ISBLANK(Tareas!B10)," - ",Tareas!B10) -> 5. Definición del entorno de desarrollo | N14: 0.3 | O14: 0 | P14: 0 | Q14: 0 | R14: 0 | S14: 0 | T14: 0 | U14: 0
B15: =IF(ISBLANK(Tareas!B11)," - ",Tareas!B11) -> 6. Reunión 2 | C15: 0 | D15: 0.5 | E15: 0 | F15: 0 | G15: 0 | H15: 0 | I15: 0 | J15: 0 | M15: =IF(ISBLANK(Tareas!B11)," - ",Tareas!B11) -> 6. Reunión 2 | N15: 0 | O15: 1 | P15: 0 | Q15: 0 | R15: 0 | S15: 0 | T15: 0 | U15: 0
B16: =IF(ISBLANK(Tareas!B12)," - ",Tareas!B12) -> 7. Realización del análisis de requisitos (ERS) | C16: 0 | D16: 0 | E16: 0 | F16: 0 | G16: 0 | H16: 0 | I16: 0 | J16: 0 | M16: =IF(ISBLANK(Tareas!B12)," - ",Tareas!B12) -> 7. Realización del análisis de requisitos (ERS) | N16: 0 | O16: 0 | P16: 0 | Q16: 0 | R16: 0 | S16: 0 | T16: 0 | U16: 0
B17: =IF(ISBLANK(Tareas!B13)," - ",Tareas!B13) -> 8. Reunión 3 | C17: 0 | D17: 0 | E17: 0.5 | F17: 0 | G17: 0 | H17: 0 | I17: 0 | J17: 0 | M17: =IF(ISBLANK(Tareas!B13)," - ",Tareas!B13) -> 8. Reunión 3 | N17: 0 | O17: 0 | P17: 1 | Q17: 0 | R17: 0 | S17: 0 | T17: 0 | U17: 0
B18: =IF(ISBLANK(Tareas!B14)," - ",Tareas!B14) -> 9. Revisión del análisis de requisitos | C18: 0 | D18: 0 | E18: 1 | F18: 0 | G18: 0 | H18: 0 | I18: 0 | J18: 0 | M18: =IF(ISBLANK(Tareas!B14)," - ",Tareas!B14) -> 9. Revisión del análisis de requisitos | N18: 0 | O18: 0 | P18: 0.3 | Q18: 0 | R18: 0 | S18: 0 | T18: 0 | U18: 0
B19: =IF(ISBLANK(Tareas!B15)," - ",Tareas!B15) -> 10. Disposición del ERS en la línea base (GCS) | C19: 0 | D19: 0 | E19: 0 | F19: 0 | G19: 0 | H19: 0 | I19: 0 | J19: 0 | M19: =IF(ISBLANK(Tareas!B15)," - ",Tareas!B15) -> 10. Disposición del ERS en la línea base (GCS) | N19: 0 | O19: 0 | P19: 0 | Q19: 0 | R19: 0 | S19: 0 | T19: 0 | U19: 0
B20: =IF(ISBLANK(Tareas!B16)," - ",Tareas!B16) -> 11. Definición del plan para el ciclo de vida 1 | C20: 0 | D20: 0 | E20: 0.3 | F20: 0 | G20: 0 | H20: 0 | I20: 0 | J20: 0 | M20: =IF(ISBLANK(Tareas!B16)," - ",Tareas!B16) -> 11. Definición del plan para el ciclo de vida 1 | N20: 0 | O20: 0 | P20: 0.3 | Q20: 0 | R20: 0 | S20: 0 | T20: 0 | U20: 0
B21: =IF(ISBLANK(Tareas!B17)," - ",Tareas!B17) -> 12. Definición de los casos de uso y el modelo E/R | C21: 0 | D21: 0 | E21: 0 | F21: 0 | G21: 0 | H21: 0 | I21: 0 | J21: 0 | M21: =IF(ISBLANK(Tareas!B17)," - ",Tareas!B17) -> 12. Definición de los casos de uso y el modelo E/R | N21: 0 | O21: 0 | P21: 0 | Q21: 0 | R21: 0 | S21: 0 | T21: 0 | U21: 0
... B62: =IF(ISBLANK(Tareas!B58)," - ",Tareas!B58) -> 53. Entrega del ciclo de vida | C62: 0 | D62: 0 | E62: 0 | F62: 0 | G62: 0 | H62: 0 | I62: 0 | J62: 0.5 | M62: =IF(ISBLANK(Tareas!B58)," - ",Tareas!B58) -> 53. Entrega del ciclo de vida | N62: 0 | O62: 0 | P62: 0 | Q62: 0 | R62: 0 | S62: 0 | T62: 0 | U62: 0.5
B63: =IF(ISBLANK(Tareas!B59)," - ",Tareas!B59) -> - | M63: =IF(ISBLANK(Tareas!B59)," - ",Tareas!B59) -> -
B64: =IF(ISBLANK(Tareas!B60)," - ",Tareas!B60) -> - | M64: =IF(ISBLANK(Tareas!B60)," - ",Tareas!B60) -> -
B65: =IF(ISBLANK(Tareas!B61)," - ",Tareas!B61) -> - | M65: =IF(ISBLANK(Tareas!B61)," - ",Tareas!B61) -> -
B66: =IF(ISBLANK(Tareas!B62)," - ",Tareas!B62) -> - | M66: =IF(ISBLANK(Tareas!B62)," - ",Tareas!B62) -> -
B67: =IF(ISBLANK(Tareas!B63)," - ",Tareas!B63) -> - | M67: =IF(ISBLANK(Tareas!B63)," - ",Tareas!B63) -> -
B68: =IF(ISBLANK(Tareas!B64)," - ",Tareas!B64) -> - | M68: =IF(ISBLANK(Tareas!B64)," - ",Tareas!B64) -> -
B69: =IF(ISBLANK(Tareas!B65)," - ",Tareas!B65) -> - | M69: =IF(ISBLANK(Tareas!B65)," - ",Tareas!B65) -> -
B70: =IF(ISBLANK(Tareas!B66)," - ",Tareas!B66) -> - | M70: =IF(ISBLANK(Tareas!B66)," - ",Tareas!B66) -> -
B71: =IF(ISBLANK(Tareas!B67)," - ",Tareas!B67) -> - | M71: =IF(ISBLANK(Tareas!B67)," - ",Tareas!B67) -> -
B72: =IF(ISBLANK(Tareas!B68)," - ",Tareas!B68) -> - | M72: =IF(ISBLANK(Tareas!B68)," - ",Tareas!B68) -> -
B73: =IF(ISBLANK(Tareas!B69)," - ",Tareas!B69) -> - | M73: =IF(ISBLANK(Tareas!B69)," - ",Tareas!B69) -> -
B74: =IF(ISBLANK(Tareas!B70)," - ",Tareas!B70) -> - | M74: =IF(ISBLANK(Tareas!B70)," - ",Tareas!B70) -> -
... B200: =IF(ISBLANK(Tareas!B196)," - ",Tareas!B196) -> - | M200: =IF(ISBLANK(Tareas!B196)," - ",Tareas!B196) -> -

Sheet LG
A1: Coste Reales y Costes Planificados
B2: En esta hoja se introducen los valores para cada tarea tanto reales de las horas trabajo del miembro de equipo asi como las horas que tuviera planificadas
B3: Asegurate que los nombres de las tareas son los mismos que el plan
A7: Horas Reales (AC) del Trabajo Planificado | L7: Horas Planificadas (PV)
B9: Nombre Tarea | C9: =Informe!D22 -> S1 | D9: =Informe!E22 -> S2 | E9: =Informe!F22 -> S3 | F9: =Informe!G22 -> S4 | G9: =Informe!H22 -> S5 | H9: =Informe!I22 -> S6 | I9: =Informe!J22 -> S7 | J9: =Informe!K22 -> S8 | M9: Nombre Tarea | N9: =Informe!D22 -> S1 | O9: =Informe!E22 -> S2 | P9: =Informe!F22 -> S3 | Q9: =Informe!G22 -> S4 | R9: =Informe!H22 -> S5 | S9: =Informe!I22 -> S6 | T9: =Informe!J22 -> S7 | U9: =Informe!K22 -> S8
B10: =IF(ISBLANK(Tareas!B6)," - ",Tareas!B6) -> 1. Reunión 1 | C10: 0.5 | D10: 0 | E10: 0 | F10: 0 | G10: 0 | H10: 0 | I10: 0 | J10: 0 | M10: =IF(ISBLANK(Tareas!B6)," - ",Tareas!B6) -> 1. Reunión 1 | N10: 1 | O10: 0 | P10: 0 | Q10: 0 | R10: 0 | S10: 0 | T10: 0 | U10: 0
B11: =IF(ISBLANK(Tareas!B7)," - ",Tareas!B7) -> 2. Asignación de roles | C11: 0 | D11: 0 | E11: 0 | F11: 0 | G11: 0 | H11: 0 | I11: 0 | J11: 0 | M11: =IF(ISBLANK(Tareas!B7)," - ",Tareas!B7) -> 2. Asignación de roles | N11: 0 | O11: 0 | P11: 0 | Q11: 0 | R11: 0 | S11: 0 | T11: 0 | U11: 0
B12: =IF(ISBLANK(Tareas!B8)," - ",Tareas!B8) -> 3. Definición del estándar de documentación | C12: 0 | D12: 0 | E12: 0 | F12: 0 | G12: 0 | H12: 0 | I12: 0 | J12: 0 | M12: =IF(ISBLANK(Tareas!B8)," - ",Tareas!B8) -> 3. Definición del estándar de documentación | N12: 0 | O12: 0 | P12: 0 | Q12: 0 | R12: 0 | S12: 0 | T12: 0 | U12: 0
B13: =IF(ISBLANK(Tareas!B9)," - ",Tareas!B9) -> 4. Definición del estándar de proceso | C13: 0 | D13: 0 | E13: 0 | F13: 0 | G13: 0 | H13: 0 | I13: 0 | J13: 0 | M13: =IF(ISBLANK(Tareas!B9)," - ",Tareas!B9) -> 4. Definición del estándar de proceso | N13: 0.3 | O13: 0 | P13: 0 | Q13: 0 | R13: 0 | S13: 0 | T13: 0 | U13: 0
B14: =IF(ISBLANK(Tareas!B10)," - ",Tareas!B10) -> 5. Definición del entorno de desarrollo | C14: 0 | D14: 0 | E14: 0 | F14: 0 | G14: 0 | H14: 0 | I14: 0 | J14: 0 | M14: =IF(ISBLANK(Tareas!B10)," - ",Tareas!B10) -> 5. Definición del entorno de desarrollo | N14: 0 | O14: 0 | P14: 0 | Q14: 0 | R14: 0 | S14: 0 | T14: 0 | U14: 0
B15: =IF(ISBLANK(Tareas!B11)," - ",Tareas!B11) -> 6. Reunión 2 | C15: 0 | D15: 0.5 | E15: 0 | F15: 0 | G15: 0 | H15: 0 | I15: 0 | J15: 0 | M15: =IF(ISBLANK(Tareas!B11)," - ",Tareas!B11) -> 6. Reunión 2 | N15: 0 | O15: 1 | P15: 0 | Q15: 0 | R15: 0 | S15: 0 | T15: 0 | U15: 0
B16: =IF(ISBLANK(Tareas!B12)," - ",Tareas!B12) -> 7. Realización del análisis de requisitos (ERS) | C16: 0 | D16: 0 | E16: 0 | F16: 0 | G16: 0 | H16: 0 | I16: 0 | J16: 0 | M16: =IF(ISBLANK(Tareas!B12)," - ",Tareas!B12) -> 7. Realización del análisis de requisitos (ERS) | N16: 0 | O16: 0 | P16: 0 | Q16: 0 | R16: 0 | S16: 0 | T16: 0 | U16: 0
B17: =IF(ISBLANK(Tareas!B13)," - ",Tareas!B13) -> 8. Reunión 3 | C17: 0 | D17: 0 | E17: 0.5 | F17: 0 | G17: 0 | H17: 0 | I17: 0 | J17: 0 | M17: =IF(ISBLANK(Tareas!B13)," - ",Tareas!B13) -> 8. Reunión 3 | N17: 0 | O17: 0 | P17: 1 | Q17: 0 | R17: 0 | S17: 0 | T17: 0 | U17: 0
B18: =IF(ISBLANK(Tareas!B14)," - ",Tareas!B14) -> 9. Revisión del análisis de requisitos | C18: 0 | D18: 0 | E18: 0.3 | F18: 0 | G18: 0 | H18: 0 | I18: 0 | J18: 0 | M18: =IF(ISBLANK(Tareas!B14)," - ",Tareas!B14) -> 9. Revisión del análisis de requisitos | N18: 0 | O18: 0 | P18: 0.2 | Q18: 0 | R18: 0 | S18: 0 | T18: 0 | U18: 0
B19: =IF(ISBLANK(Tareas!B15)," - ",Tareas!B15) -> 10. Disposición del ERS en la línea base (GCS) | C19: 0 | D19: 0 | E19: 0 | F19: 0 | G19: 0 | H19: 0 | I19: 0 | J19: 0 | M19: =IF(ISBLANK(Tareas!B15)," - ",Tareas!B15) -> 10. Disposición del ERS en la línea base (GCS) | N19: 0 | O19: 0 | P19: 0 | Q19: 0 | R19: 0 | S19: 0 | T19: 0 | U19: 0
B20: =IF(ISBLANK(Tareas!B16)," - ",Tareas!B16) -> 11. Definición del plan para el ciclo de vida 1 | C20: 0 | D20: 0 | E20: 0.3 | F20: 0 | G20: 0 | H20: 0 | I20: 0 | J20: 0 | M20: =IF(ISBLANK(Tareas!B16)," - ",Tareas!B16) -> 11. Definición del plan para el ciclo de vida 1 | N20: 0 | O20: 0 | P20: 0.3 | Q20: 0 | R20: 0 | S20: 0 | T20: 0 | U20: 0
B21: =IF(ISBLANK(Tareas!B17)," - ",Tareas!B17) -> 12. Definición de los casos de uso y el modelo E/R | C21: 0 | D21: 0 | E21: 0 | F21: 0 | G21: 0 | H21: 0 | I21: 0 | J21: 0 | M21: =IF(ISBLANK(Tareas!B17)," - ",Tareas!B17) -> 12. Definición de los casos de uso y el modelo E/R | N21: 0 | O21: 0 | P21: 0 | Q21: 0 | R21: 0 | S21: 0 | T21: 0 | U21: 0
... B62: =IF(ISBLANK(Tareas!B58)," - ",Tareas!B58) -> 53. Entrega del ciclo de vida | C62: 0 | D62: 0 | E62: 0 | F62: 0 | G62: 0 | H62: 0 | I62: 0 | J62: 0 | M62: =IF(ISBLANK(Tareas!B58)," - ",Tareas!B58) -> 53. Entrega del ciclo de vida | N62: 0 | O62: 0 | P62: 0 | Q62: 0 | R62: 0 | S62: 0 | T62: 0 | U62: 0
B63: =IF(ISBLANK(Tareas!B59)," - ",Tareas!B59) -> - | M63: =IF(ISBLANK(Tareas!B59)," - ",Tareas!B59) -> -
B64: =IF(ISBLANK(Tareas!B60)," - ",Tareas!B60) -> - | M64: =IF(ISBLANK(Tareas!B60)," - ",Tareas!B60) -> -
B65: =IF(ISBLANK(Tareas!B61)," - ",Tareas!B61) -> - | M65: =IF(ISBLANK(Tareas!B61)," - ",Tareas!B61) -> -
B66: =IF(ISBLANK(Tareas!B62)," - ",Tareas!B62) -> - | M66: =IF(ISBLANK(Tareas!B62)," - ",Tareas!B62) -> -
B67: =IF(ISBLANK(Tareas!B63)," - ",Tareas!B63) -> - | M67: =IF(ISBLANK(Tareas!B63)," - ",Tareas!B63) -> -
B68: =IF(ISBLANK(Tareas!B64)," - ",Tareas!B64) -> - | M68: =IF(ISBLANK(Tareas!B64)," - ",Tareas!B64) -> -
B69: =IF(ISBLANK(Tareas!B65)," - ",Tareas!B65) -> - | M69: =IF(ISBLANK(Tareas!B65)," - ",Tareas!B65) -> -
B70: =IF(ISBLANK(Tareas!B66)," - ",Tareas!B66) -> - | M70: =IF(ISBLANK(Tareas!B66)," - ",Tareas!B66) -> -
B71: =IF(ISBLANK(Tareas!B67)," - ",Tareas!B67) -> - | M71: =IF(ISBLANK(Tareas!B67)," - ",Tareas!B67) -> -
B72: =IF(ISBLANK(Tareas!B68)," - ",Tareas!B68) -> - | M72: =IF(ISBLANK(Tareas!B68)," - ",Tareas!B68) -> -
B73: =IF(ISBLANK(Tareas!B69)," - ",Tareas!B69) -> - | M73: =IF(ISBLANK(Tareas!B69)," - ",Tareas!B69) -> -
B74: =IF(ISBLANK(Tareas!B70)," - ",Tareas!B70) -> - | M74: =IF(ISBLANK(Tareas!B70)," - ",Tareas!B70) -> -
... B201: =IF(ISBLANK(Tareas!B197)," - ",Tareas!B197) -> - | M201: =IF(ISBLANK(Tareas!B197)," - ",Tareas!B197) -> -

Sheet JR
A1: Coste Reales y Costes Planificados
B2: En esta hoja se introducen los valores para cada tarea tanto reales de las horas trabajo del miembro de equipo asi como las horas que tuviera planificadas
B3: Asegurate que los nombres de las tareas son los mismos que el plan
A7: Horas Reales (AC) del Trabajo Planificado | L7: Horas Planificadas (PV)
B9: Nombre Tarea | C9: =Informe!D22 -> S1 | D9: =Informe!E22 -> S2 | E9: =Informe!F22 -> S3 | F9: =Informe!G22 -> S4 | G9: =Informe!H22 -> S5 | H9: =Informe!I22 -> S6 | I9: =Informe!J22 -> S7 | J9: =Informe!K22 -> S8 | M9: Nombre Tarea | N9: =Informe!D22 -> S1 | O9: =Informe!E22 -> S2 | P9: =Informe!F22 -> S3 | Q9: =Informe!G22 -> S4 | R9: =Informe!H22 -> S5 | S9: =Informe!I22 -> S6 | T9: =Informe!J22 -> S7 | U9: =Informe!K22 -> S8
B10: =IF(ISBLANK(Tareas!B6)," - ",Tareas!B6) -> 1. Reunión 1 | C10: 0.5 | D10: 0 | E10: 0 | F10: 0 | G10: 0 | H10: 0 | I10: 0 | J10: 0 | M10: =IF(ISBLANK(Tareas!B6)," - ",Tareas!B6) -> 1. Reunión 1 | N10: 1 | O10: 0 | P10: 0 | Q10: 0 | R10: 0 | S10: 0 | T10: 0 | U10: 0
B11: =IF(ISBLANK(Tareas!B7)," - ",Tareas!B7) -> 2. Asignación de roles | C11: 0.5 | D11: 0 | E11: 0 | F11: 0 | G11: 0 | H11: 0 | I11: 0 | J11: 0 | M11: =IF(ISBLANK(Tareas!B7)," - ",Tareas!B7) -> 2. Asignación de roles | N11: 0.3 | O11: 0 | P11: 0 | Q11: 0 | R11: 0 | S11: 0 | T11: 0 | U11: 0
B12: =IF(ISBLANK(Tareas!B8)," - ",Tareas!B8) -> 3. Definición del estándar de documentación | C12: 0.5 | D12: 0 | E12: 0 | F12: 0 | G12: 0 | H12: 0 | I12: 0 | J12: 0 | M12: =IF(ISBLANK(Tareas!B8)," - ",Tareas!B8) -> 3. Definición del estándar de documentación | N12: 0.2 | O12: 0 | P12: 0 | Q12: 0 | R12: 0 | S12: 0 | T12: 0 | U12: 0
B13: =IF(ISBLANK(Tareas!B9)," - ",Tareas!B9) -> 4. Definición del estándar de proceso | C13: 0 | D13: 0 | E13: 0 | F13: 0 | G13: 0 | H13: 0 | I13: 0 | J13: 0 | M13: =IF(ISBLANK(Tareas!B9)," - ",Tareas!B9) -> 4. Definición del estándar de proceso | N13: 0.3 | O13: 0 | P13: 0 | Q13: 0 | R13: 0 | S13: 0 | T13: 0 | U13: 0
B14: =IF(ISBLANK(Tareas!B10)," - ",Tareas!B10) -> 5. Definición del entorno de desarrollo | C14: 0.3 | D14: 0 | E14: 0 | F14: 0 | G14: 0 | H14: 0 | I14: 0 | J14: 0 | M14: =IF(ISBLANK(Tareas!B10)," - ",Tareas!B10) -> 5. Definición del entorno de desarrollo | N14: 0.3 | O14: 0 | P14: 0 | Q14: 0 | R14: 0 | S14: 0 | T14: 0 | U14: 0
B15: =IF(ISBLANK(Tareas!B11)," - ",Tareas!B11) -> 6. Reunión 2 | C15: 0 | D15: 0.5 | E15: 0 | F15: 0 | G15: 0 | H15: 0 | I15: 0 | J15: 0 | M15: =IF(ISBLANK(Tareas!B11)," - ",Tareas!B11) -> 6. Reunión 2 | N15: 0 | O15: 1 | P15: 0 | Q15: 0 | R15: 0 | S15: 0 | T15: 0 | U15: 0
B16: =IF(ISBLANK(Tareas!B12)," - ",Tareas!B12) -> 7. Realización del análisis de requisitos (ERS) | C16: 0 | D16: 1.5 | E16: 0 | F16: 0 | G16: 0 | H16: 0 | I16: 0 | J16: 0 | M16: =IF(ISBLANK(Tareas!B12)," - ",Tareas!B12) -> 7. Realización del análisis de requisitos (ERS) | N16: 0 | O16: 2 | P16: 0 | Q16: 0 | R16: 0 | S16: 0 | T16: 0 | U16: 0
B17: =IF(ISBLANK(Tareas!B13)," - ",Tareas!B13) -> 8. Reunión 3 | C17: 0 | D17: 0 | E17: 0.5 | F17: 0 | G17: 0 | H17: 0 | I17: 0 | J17: 0 | M17: =IF(ISBLANK(Tareas!B13)," - ",Tareas!B13) -> 8. Reunión 3 | N17: 0 | O17: 0 | P17: 1 | Q17: 0 | R17: 0 | S17: 0 | T17: 0 | U17: 0
B18: =IF(ISBLANK(Tareas!B14)," - ",Tareas!B14) -> 9. Revisión del análisis de requisitos | C18: 0 | D18: 0 | E18: 0.5 | F18: 0 | G18: 0 | H18: 0 | I18: 0 | J18: 0 | M18: =IF(ISBLANK(Tareas!B14)," - ",Tareas!B14) -> 9. Revisión del análisis de requisitos | N18: 0 | O18: 0 | P18: 0.2 | Q18: 0 | R18: 0 | S18: 0 | T18: 0 | U18: 0
B19: =IF(ISBLANK(Tareas!B15)," - ",Tareas!B15) -> 10. Disposición del ERS en la línea base (GCS) | C19: 0 | D19: 0 | E19: 0 | F19: 0 | G19: 0 | H19: 0 | I19: 0 | J19: 0 | M19: =IF(ISBLANK(Tareas!B15)," - ",Tareas!B15) -> 10. Disposición del ERS en la línea base (GCS) | N19: 0 | O19: 0 | P19: 0 | Q19: 0 | R19: 0 | S19: 0 | T19: 0 | U19: 0
B20: =IF(ISBLANK(Tareas!B16)," - ",Tareas!B16) -> 11. Definición del plan para el ciclo de vida 1 | C20: 0 | D20: 0 | E20: 0.3 | F20: 0 | G20: 0 | H20: 0 | I20: 0 | J20: 0 | M20: =IF(ISBLANK(Tareas!B16)," - ",Tareas!B16) -> 11. Definición del plan para el ciclo de vida 1 | N20: 0 | O20: 0 | P20: 0.3 | Q20: 0 | R20: 0 | S20: 0 | T20: 0 | U20: 0
B21: =IF(ISBLANK(Tareas!B17)," - ",Tareas!B17) -> 12. Definición de los casos de uso y el modelo E/R | C21: 0 | D21: 0 | E21: 0.5 | F21: 0 | G21: 0 | H21: 0 | I21: 0 | J21: 0 | M21: =IF(ISBLANK(Tareas!B17)," - ",Tareas!B17) -> 12. Definición de los casos de uso y el modelo E/R | N21: 0 | O21: 0 | P21: 1 | Q21: 0 | R21: 0 | S21: 0 | T21: 0 | U21: 0
... B62: =IF(ISBLANK(Tareas!B58)," - ",Tareas!B58) -> 53. Entrega del ciclo de vida | C62: 0 | D62: 0 | E62: 0 | F62: 0 | G62: 0 | H62: 0 | I62: 0 | J62: 0.5 | M62: =IF(ISBLANK(Tareas!B58)," - ",Tareas!B58) -> 53. Entrega del ciclo de vida | N62: 0 | O62: 0 | P62: 0 | Q62: 0 | R62: 0 | S62: 0 | T62: 0 | U62: 0.3
B63: =IF(ISBLANK(Tareas!B59)," - ",Tareas!B59) -> - | M63: =IF(ISBLANK(Tareas!B59)," - ",Tareas!B59) -> -
B64: =IF(ISBLANK(Tareas!B60)," - ",Tareas!B60) -> - | M64: =IF(ISBLANK(Tareas!B60)," - ",Tareas!B60) -> -
B65: =IF(ISBLANK(Tareas!B61)," - ",Tareas!B61) -> - | M65: =IF(ISBLANK(Tareas!B61)," - ",Tareas!B61) -> -
B66: =IF(ISBLANK(Tareas!B62)," - ",Tareas!B62) -> - | M66: =IF(ISBLANK(Tareas!B62)," - ",Tareas!B62) -> -
B67: =IF(ISBLANK(Tareas!B63)," - ",Tareas!B63) -> - | M67: =IF(ISBLANK(Tareas!B63)," - ",Tareas!B63) -> -
B68: =IF(ISBLANK(Tareas!B64)," - ",Tareas!B64) -> - | M68: =IF(ISBLANK(Tareas!B64)," - ",Tareas!B64) -> -
B69: =IF(ISBLANK(Tareas!B65)," - ",Tareas!B65) -> - | M69: =IF(ISBLANK(Tareas!B65)," - ",Tareas!B65) -> -
B70: =IF(ISBLANK(Tareas!B66)," - ",Tareas!B66) -> - | M70: =IF(ISBLANK(Tareas!B66)," - ",Tareas!B66) -> -
B71: =IF(ISBLANK(Tareas!B67)," - ",Tareas!B67) -> - | M71: =IF(ISBLANK(Tareas!B67)," - ",Tareas!B67) -> -
B72: =IF(ISBLANK(Tareas!B68)," - ",Tareas!B68) -> - | M72: =IF(ISBLANK(Tareas!B68)," - ",Tareas!B68) -> -
B73: =IF(ISBLANK(Tareas!B69)," - ",Tareas!B69) -> - | M73: =IF(ISBLANK(Tareas!B69)," - ",Tareas!B69) -> -
B74: =IF(ISBLANK(Tareas!B70)," - ",Tareas!B70) -> - | M74: =IF(ISBLANK(Tareas!B70)," - ",Tareas!B70) -> -
... B201: =IF(ISBLANK(Tareas!B197)," - ",Tareas!B197) -> - | M201: =IF(ISBLANK(Tareas!B197)," - ",Tareas!B197) -> -

Sheet VG
A1: Coste Reales y Costes Planificados
B2: En esta hoja se introducen los valores para cada tarea tanto reales de las horas trabajo del miembro de equipo asi como las horas que tuviera planificadas
B3: Asegurate que los nombres de las tareas son los mismos que el plan
A7: Horas Reales (AC) del Trabajo Planificado | L7: Horas Planificadas (PV)
B9: Nombre Tarea | C9: =Informe!D22 -> S1 | D9: =Informe!E22 -> S2 | E9: =Informe!F22 -> S3 | F9: =Informe!G22 -> S4 | G9: =Informe!H22 -> S5 | H9: =Informe!I22 -> S6 | I9: =Informe!J22 -> S7 | J9: =Informe!K22 -> S8 | M9: Nombre Tarea | N9: =Informe!D22 -> S1 | O9: =Informe!E22 -> S2 | P9: =Informe!F22 -> S3 | Q9: =Informe!G22 -> S4 | R9: =Informe!H22 -> S5 | S9: =Informe!I22 -> S6 | T9: =Informe!J22 -> S7 | U9: =Informe!K22 -> S8
B10: =IF(ISBLANK(Tareas!B6)," - ",Tareas!B6) -> 1. Reunión 1 | C10: 0.5 | D10: 0 | E10: 0 | F10: 0 | G10: 0 | H10: 0 | I10: 0 | J10: 0 | M10: =IF(ISBLANK(Tareas!B6)," - ",Tareas!B6) -> 1. Reunión 1 | N10: 1 | O10: 0 | P10: 0 | Q10: 0 | R10: 0 | S10: 0 | T10: 0 | U10: 0
B11: =IF(ISBLANK(Tareas!B7)," - ",Tareas!B7) -> 2. Asignación de roles | C11: 0.5 | D11: 0 | E11: 0 | F11: 0 | G11: 0 | H11: 0 | I11: 0 | J11: 0 | M11: =IF(ISBLANK(Tareas!B7)," - ",Tareas!B7) -> 2. Asignación de roles | N11: 0.3 | O11: 0 | P11: 0 | Q11: 0 | R11: 0 | S11: 0 | T11: 0 | U11: 0
B12: =IF(ISBLANK(Tareas!B8)," - ",Tareas!B8) -> 3. Definición del estándar de documentación | C12: 0 | D12: 0 | E12: 0 | F12: 0 | G12: 0 | H12: 0 | I12: 0 | J12: 0 | M12: =IF(ISBLANK(Tareas!B8)," - ",Tareas!B8) -> 3. Definición del estándar de documentación | N12: 0 | O12: 0 | P12: 0 | Q12: 0 | R12: 0 | S12: 0 | T12: 0 | U12: 0
B13: =IF(ISBLANK(Tareas!B9)," - ",Tareas!B9) -> 4. Definición del estándar de proceso | C13: 0 | D13: 0 | E13: 0 | F13: 0 | G13: 0 | H13: 0 | I13: 0 | J13: 0 | M13: =IF(ISBLANK(Tareas!B9)," - ",Tareas!B9) -> 4. Definición del estándar de proceso | N13: 0.3 | O13: 0 | P13: 0 | Q13: 0 | R13: 0 | S13: 0 | T13: 0 | U13: 0
B14: =IF(ISBLANK(Tareas!B10)," - ",Tareas!B10) -> 5. Definición del entorno de desarrollo | C14: 0 | D14: 0 | E14: 0 | F14: 0 | G14: 0 | H14: 0 | I14: 0 | J14: 0 | M14: =IF(ISBLANK(Tareas!B10)," - ",Tareas!B10) -> 5. Definición del entorno de desarrollo | N14: 0 | O14: 0 | P14: 0 | Q14: 0 | R14: 0 | S14: 0 | T14: 0 | U14: 0
B15: =IF(ISBLANK(Tareas!B11)," - ",Tareas!B11) -> 6. Reunión 2 | C15: 0 | D15: 0.5 | E15: 0 | F15: 0 | G15: 0 | H15: 0 | I15: 0 | J15: 0 | M15: =IF(ISBLANK(Tareas!B11)," - ",Tareas!B11) -> 6. Reunión 2 | N15: 0 | O15: 1 | P15: 0 | Q15: 0 | R15: 0 | S15: 0 | T15: 0 | U15: 0
B16: =IF(ISBLANK(Tareas!B12)," - ",Tareas!B12) -> 7. Realización del análisis de requisitos (ERS) | C16: 0 | D16: 1.5 | E16: 0.3 | F16: 0 | G16: 0 | H16: 0 | I16: 0 | J16: 0 | M16: =IF(ISBLANK(Tareas!B12)," - ",Tareas!B12) -> 7. Realización del análisis de requisitos (ERS) | N16: 0 | O16: 2 | P16: 0 | Q16: 0 | R16: 0 | S16: 0 | T16: 0 | U16: 0
B17: =IF(ISBLANK(Tareas!B13)," - ",Tareas!B13) -> 8. Reunión 3 | C17: 0 | D17: 0 | E17: 0.5 | F17: 0 | G17: 0 | H17: 0 | I17: 0 | J17: 0 | M17: =IF(ISBLANK(Tareas!B13)," - ",Tareas!B13) -> 8. Reunión 3 | N17: 0 | O17: 0 | P17: 1 | Q17: 0 | R17: 0 | S17: 0 | T17: 0 | U17: 0
B18: =IF(ISBLANK(Tareas!B14)," - ",Tareas!B14) -> 9. Revisión del análisis de requisitos | C18: 0 | D18: 0 | E18: 0.5 | F18: 0 | G18: 0 | H18: 0 | I18: 0 | J18: 0 | M18: =IF(ISBLANK(Tareas!B14)," - ",Tareas!B14) -> 9. Revisión del análisis de requisitos | N18: 0 | O18: 0 | P18: 0.2 | Q18: 0 | R18: 0 | S18: 0 | T18: 0 | U18: 0
B19: =IF(ISBLANK(Tareas!B15)," - ",Tareas!B15) -> 10. Disposición del ERS en la línea base (GCS) | C19: 0 | D19: 0 | E19: 0.3 | F19: 0 | G19: 0 | H19: 0 | I19: 0 | J19: 0 | M19: =IF(ISBLANK(Tareas!B15)," - ",Tareas!B15) -> 10. Disposición del ERS en la línea base (GCS) | N19: 0 | O19: 0 | P19: 0.3 | Q19: 0 | R19: 0 | S19: 0 | T19: 0 | U19: 0
B20: =IF(ISBLANK(Tareas!B16)," - ",Tareas!B16) -> 11. Definición del plan para el ciclo de vida 1 | C20: 0 | D20: 0 | E20: 0.3 | F20: 0 | G20: 0 | H20: 0 | I20: 0 | J20: 0 | M20: =IF(ISBLANK(Tareas!B16)," - ",Tareas!B16) -> 11. Definición del plan para el ciclo de vida 1 | N20: 0 | O20: 0 | P20: 0.3 | Q20: 0 | R20: 0 | S20: 0 | T20: 0 | U20: 0
B21: =IF(ISBLANK(Tareas!B17)," - ",Tareas!B17) -> 12. Definición de los casos de uso y el modelo E/R | C21: 0 | D21: 0 | E21: 0.3 | F21: 0 | G21: 0 | H21: 0 | I21: 0 | J21: 0 | M21: =IF(ISBLANK(Tareas!B17)," - ",Tareas!B17) -> 12. Definición de los casos de uso y el modelo E/R | N21: 0 | O21: 0 | P21: 1 | Q21: 0 | R21: 0 | S21: 0 | T21: 0 | U21: 0
... B62: =IF(ISBLANK(Tareas!B58)," - ",Tareas!B58) -> 53. Entrega del ciclo de vida | C62: 0 | D62: 0 | E62: 0 | F62: 0 | G62: 0 | H62: 0 | I62: 0 | J62: 0 | M62: =IF(ISBLANK(Tareas!B58)," - ",Tareas!B58) -> 53. Entrega del ciclo de vida | N62: 0 | O62: 0 | P62: 0 | Q62: 0 | R62: 0 | S62: 0 | T62: 0 | U62: 0
B63: =IF(ISBLANK(Tareas!B59)," - ",Tareas!B59) -> - | M63: =IF(ISBLANK(Tareas!B59)," - ",Tareas!B59) -> -
B64: =IF(ISBLANK(Tareas!B60)," - ",Tareas!B60) -> - | M64: =IF(ISBLANK(Tareas!B60)," - ",Tareas!B60) -> -
B65: =IF(ISBLANK(Tareas!B61)," - ",Tareas!B61) -> - | M65: =IF(ISBLANK(Tareas!B61)," - ",Tareas!B61) -> -
B66: =IF(ISBLANK(Tareas!B62)," - ",Tareas!B62) -> - | M66: =IF(ISBLANK(Tareas!B62)," - ",Tareas!B62) -> -
B67: =IF(ISBLANK(Tareas!B63)," - ",Tareas!B63) -> - | M67: =IF(ISBLANK(Tareas!B63)," - ",Tareas!B63) -> -
B68: =IF(ISBLANK(Tareas!B64)," - ",Tareas!B64) -> - | M68: =IF(ISBLANK(Tareas!B64)," - ",Tareas!B64) -> -
B69: =IF(ISBLANK(Tareas!B65)," - ",Tareas!B65) -> - | M69: =IF(ISBLANK(Tareas!B65)," - ",Tareas!B65) -> -
B70: =IF(ISBLANK(Tareas!B66)," - ",Tareas!B66) -> - | M70: =IF(ISBLANK(Tareas!B66)," - ",Tareas!B66) -> -
B71: =IF(ISBLANK(Tareas!B67)," - ",Tareas!B67) -> - | M71: =IF(ISBLANK(Tareas!B67)," - ",Tareas!B67) -> -
B72: =IF(ISBLANK(Tareas!B68)," - ",Tareas!B68) -> - | M72: =IF(ISBLANK(Tareas!B68)," - ",Tareas!B68) -> -
B73: =IF(ISBLANK(Tareas!B69)," - ",Tareas!B69) -> - | M73: =IF(ISBLANK(Tareas!B69)," - ",Tareas!B69) -> -
B74: =IF(ISBLANK(Tareas!B70)," - ",Tareas!B70) -> - | M74: =IF(ISBLANK(Tareas!B70)," - ",Tareas!B70) -> -
... B201: =IF(ISBLANK(Tareas!B197)," - ",Tareas!B197) -> - | M201: =IF(ISBLANK(Tareas!B197)," - ",Tareas!B197) -> -

Sheet LM
A1: Coste Reales y Costes Planificados
B2: En esta hoja se introducen los valores para cada tarea tanto reales de las horas trabajo del miembro de equipo asi como las horas que tuviera planificadas
B3: Asegurate que los nombres de las tareas son los mismos que el plan
A7: Horas Reales (AC) del Trabajo Planificado | L7: Horas Planificadas (PV)
B9: Nombre Tarea | C9: =Informe!D22 -> S1 | D9: =Informe!E22 -> S2 | E9: =Informe!F22 -> S3 | F9: =Informe!G22 -> S4 | G9: =Informe!H22 -> S5 | H9: =Informe!I22 -> S6 | I9: =Informe!J22 -> S7 | J9: =Informe!K22 -> S8 | M9: Nombre Tarea | N9: =Informe!D22 -> S1 | O9: =Informe!E22 -> S2 | P9: =Informe!F22 -> S3 | Q9: =Informe!G22 -> S4 | R9: =Informe!H22 -> S5 | S9: =Informe!I22 -> S6 | T9: =Informe!J22 -> S7 | U9: =Informe!K22 -> S8
B10: =IF(ISBLANK(Tareas!B6)," - ",Tareas!B6) -> 1. Reunión 1 | C10: 0.5 | D10: 0 | E10: 0 | F10: 0 | G10: 0 | H10: 0 | I10: 0 | J10: 0 | M10: =IF(ISBLANK(Tareas!B6)," - ",Tareas!B6) -> 1. Reunión 1 | N10: 0.5 | O10: 0 | P10: 0 | Q10: 0 | R10: 0 | S10: 0 | T10: 0 | U10: 0
B11: =IF(ISBLANK(Tareas!B7)," - ",Tareas!B7) -> 2. Asignación de roles | C11: 0 | D11: 0 | E11: 0 | F11: 0 | G11: 0 | H11: 0 | I11: 0 | J11: 0 | M11: =IF(ISBLANK(Tareas!B7)," - ",Tareas!B7) -> 2. Asignación de roles | N11: 0 | O11: 0 | P11: 0 | Q11: 0 | R11: 0 | S11: 0 | T11: 0 | U11: 0
B12: =IF(ISBLANK(Tareas!B8)," - ",Tareas!B8) -> 3. Definición del estándar de documentación | C12: 0.5 | D12: 0 | E12: 0 | F12: 0 | G12: 0 | H12: 0 | I12: 0 | J12: 0 | M12: =IF(ISBLANK(Tareas!B8)," - ",Tareas!B8) -> 3. Definición del estándar de documentación | N12: 0.5 | O12: 0 | P12: 0 | Q12: 0 | R12: 0 | S12: 0 | T12: 0 | U12: 0
B13: =IF(ISBLANK(Tareas!B9)," - ",Tareas!B9) -> 4. Definición del estándar de proceso | C13: 1 | D13: 0 | E13: 0 | F13: 0 | G13: 0 | H13: 0 | I13: 0 | J13: 0 | M13: =IF(ISBLANK(Tareas!B9)," - ",Tareas!B9) -> 4. Definición del estándar de proceso | N13: 1 | O13: 0 | P13: 0 | Q13: 0 | R13: 0 | S13: 0 | T13: 0 | U13: 0
B14: =IF(ISBLANK(Tareas!B10)," - ",Tareas!B10) -> 5. Definición del entorno de desarrollo | C14: 0 | D14: 0 | E14: 0 | F14: 0 | G14: 0 | H14: 0 | I14: 0 | J14: 0 | M14: =IF(ISBLANK(Tareas!B10)," - ",Tareas!B10) -> 5. Definición del entorno de desarrollo | N14: 0 | O14: 0 | P14: 0 | Q14: 0 | R14: 0 | S14: 0 | T14: 0 | U14: 0
B15: =IF(ISBLANK(Tareas!B11)," - ",Tareas!B11) -> 6. Reunión 2 | C15: 0 | D15: 0.5 | E15: 0 | F15: 0 | G15: 0 | H15: 0 | I15: 0 | J15: 0 | M15: =IF(ISBLANK(Tareas!B11)," - ",Tareas!B11) -> 6. Reunión 2 | N15: 0 | O15: 0.5 | P15: 0 | Q15: 0 | R15: 0 | S15: 0 | T15: 0 | U15: 0
B16: =IF(ISBLANK(Tareas!B12)," - ",Tareas!B12) -> 7. Realización del análisis de requisitos (ERS) | C16: 0 | D16: 0 | E16: 0 | F16: 0 | G16: 0 | H16: 0 | I16: 0 | J16: 0 | M16: =IF(ISBLANK(Tareas!B12)," - ",Tareas!B12) -> 7. Realización del análisis de requisitos (ERS) | N16: 0 | O16: 0 | P16: 0 | Q16: 0 | R16: 0 | S16: 0 | T16: 0 | U16: 0
B17: =IF(ISBLANK(Tareas!B13)," - ",Tareas!B13) -> 8. Reunión 3 | C17: 0 | D17: 0 | E17: 0.5 | F17: 0 | G17: 0 | H17: 0 | I17: 0 | J17: 0 | M17: =IF(ISBLANK(Tareas!B13)," - ",Tareas!B13) -> 8. Reunión 3 | N17: 0 | O17: 0 | P17: 0.5 | Q17: 0 | R17: 0 | S17: 0 | T17: 0 | U17: 0
B18: =IF(ISBLANK(Tareas!B14)," - ",Tareas!B14) -> 9. Revisión del análisis de requisitos | C18: 0 | D18: 0 | E18: 0.5 | F18: 0 | G18: 0 | H18: 0 | I18: 0 | J18: 0 | M18: =IF(ISBLANK(Tareas!B14)," - ",Tareas!B14) -> 9. Revisión del análisis de requisitos | N18: 0 | O18: 0 | P18: 0.5 | Q18: 0 | R18: 0 | S18: 0 | T18: 0 | U18: 0
B19: =IF(ISBLANK(Tareas!B15)," - ",Tareas!B15) -> 10. Disposición del ERS en la línea base (GCS) | C19: 0 | D19: 0 | E19: 0 | F19: 0 | G19: 0 | H19: 0 | I19: 0 | J19: 0 | M19: =IF(ISBLANK(Tareas!B15)," - ",Tareas!B15) -> 10. Disposición del ERS en la línea base (GCS) | N19: 0 | O19: 0 | P19: 0 | Q19: 0 | R19: 0 | S19: 0 | T19: 0 | U19: 0
B20: =IF(ISBLANK(Tareas!B16)," - ",Tareas!B16) -> 11. Definición del plan para el ciclo de vida 1 | C20: 0 | D20: 0 | E20: 0.3 | F20: 0 | G20: 0 | H20: 0 | I20: 0 | J20: 0 | M20: =IF(ISBLANK(Tareas!B16)," - ",Tareas!B16) -> 11. Definición del plan para el ciclo de vida 1 | N20: 0 | O20: 0 | P20: 0.3 | Q20: 0 | R20: 0 | S20: 0 | T20: 0 | U20: 0
B21: =IF(ISBLANK(Tareas!B17)," - ",Tareas!B17) -> 12. Definición de los casos de uso y el modelo E/R | C21: 0 | D21: 0 | E21: 0 | F21: 0 | G21: 0 | H21: 0 | I21: 0 | J21: 0 | M21: =IF(ISBLANK(Tareas!B17)," - ",Tareas!B17) -> 12. Definición de los casos de uso y el modelo E/R | N21: 0 | O21: 0 | P21: 0 | Q21: 0 | R21: 0 | S21: 0 | T21: 0 | U21: 0
... B62: =IF(ISBLANK(Tareas!B58)," - ",Tareas!B58) -> 53. Entrega del ciclo de vida | C62: 0 | D62: 0 | E62: 0 | F62: 0 | G62: 0 | H62: 0 | I62: 0 | J62: 0 | M62: =IF(ISBLANK(Tareas!B58)," - ",Tareas!B58) -> 53. Entrega del ciclo de vida | N62: 0 | O62: 0 | P62: 0 | Q62: 0 | R62: 0 | S62: 0 | T62: 0 | U62: 0
B63: =IF(ISBLANK(Tareas!B59)," - ",Tareas!B59) -> - | M63: =IF(ISBLANK(Tareas!B59)," - ",Tareas!B59) -> -
B64: =IF(ISBLANK(Tareas!B60)," - ",Tareas!B60) -> - | M64: =IF(ISBLANK(Tareas!B60)," - ",Tareas!B60) -> -
B65: =IF(ISBLANK(Tareas!B61)," - ",Tareas!B61) -> - | M65: =IF(ISBLANK(Tareas!B61)," - ",Tareas!B61) -> -
B66: =IF(ISBLANK(Tareas!B62)," - ",Tareas!B62) -> - | M66: =IF(ISBLANK(Tareas!B62)," - ",Tareas!B62) -> -
B67: =IF(ISBLANK(Tareas!B63)," - ",Tareas!B63) -> - | M67: =IF(ISBLANK(Tareas!B63)," - ",Tareas!B63) -> -
B68: =IF(ISBLANK(Tareas!B64)," - ",Tareas!B64) -> - | M68: =IF(ISBLANK(Tareas!B64)," - ",Tareas!B64) -> -
B69: =IF(ISBLANK(Tareas!B65)," - ",Tareas!B65) -> - | M69: =IF(ISBLANK(Tareas!B65)," - ",Tareas!B65) -> -
B70: =IF(ISBLANK(Tareas!B66)," - ",Tareas!B66) -> - | M70: =IF(ISBLANK(Tareas!B66)," - ",Tareas!B66) -> -
B71: =IF(ISBLANK(Tareas!B67)," - ",Tareas!B67) -> - | M71: =IF(ISBLANK(Tareas!B67)," - ",Tareas!B67) -> -
B72: =IF(ISBLANK(Tareas!B68)," - ",Tareas!B68) -> - | M72: =IF(ISBLANK(Tareas!B68)," - ",Tareas!B68) -> -
B73: =IF(ISBLANK(Tareas!B69)," - ",Tareas!B69) -> - | M73: =IF(ISBLANK(Tareas!B69)," - ",Tareas!B69) -> -
B74: =IF(ISBLANK(Tareas!B70)," - ",Tareas!B70) -> - | M74: =IF(ISBLANK(Tareas!B70)," - ",Tareas!B70) -> -
... B201: =IF(ISBLANK(Tareas!B197)," - ",Tareas!B197) -> - | M201: =IF(ISBLANK(Tareas!B197)," - ",Tareas!B197) -> -

Sheet Tareas
A1: Lista de tareas
B2: Puedes editar tareas
B3: Puedes añadir tareas al final de la lista, el orden de esta lista será el orden para el resto de hojas
B5: Nombre Tarea
B6: 1. Reunión 1
B7: 2. Asignación de roles
B8: 3. Definición del estándar de documentación
B9: 4. Definición del estándar de proceso
B10: 5. Definición del entorno de desarrollo
B11: 6. Reunión 2
B12: 7. Realización del análisis de requisitos (ERS)
B13: 8. Reunión 3
B14: 9. Revisión del análisis de requisitos
... B44: 39. Revisión de las incidencias detectadas
B45: 40. Implementación de la gestión de degustaciones | C45: ← Puedes añadir más tareas por debajo de esta
B46: 41. Implementación de la pantalla principal (feed y menú)
B47: 42. Integración del prototipo UI
B48: 43. Definición de los casos de prueba
B49: 44. Reunión 8
B50: 45. Realización el informe de post-mortem
B51: 46. Ejecución de las pruebas
B52: 47. Control de versiones y revisión final del código
B53: 48. Revisión de la configuración y los documentos entregables
B54: 49. Revisión de los resultados de las pruebas y corrección de errores
B55: 50. Corrección del código (post-revisión)
B56: 51. Documentación de los resultados y errores de las pruebas
B57: 52. Disposición del código en la línea base (GCS)
... B200: Atención modificar las formulas si hay más tareas

Sheet PV
A1: Hoja de Valor Planificado
B2: Esta hoja calcula el coste actual de cada tarea juntando los valores de los esfuerzos de cada miembro del equipo
B3: Se puede usar para comprobar que se realiza bien la agregacion de las horas de todos los miembros
B4: Esta hoja no tocar
A7: Valor Planificado(PV) o (BCWS) | C7: Horas semanales | D7: =IF(SUM(D10:D100)>0,SUM(D10:D100),"") -> 9.4 | E7: =IF(SUM(E10:E100)>0,SUM(E10:E100),"") -> 8.5 | F7: =IF(SUM(F10:F100)>0,SUM(F10:F100),"") -> 14.2 | G7: =IF(SUM(G10:G100)>0,SUM(G10:G100),"") -> 12 | H7: =IF(SUM(H10:H100)>0,SUM(H10:H100),"") -> 8.7 | I7: =IF(SUM(I10:I100)>0,SUM(I10:I100),"") -> 7.6 | J7: =IF(SUM(J10:J100)>0,SUM(J10:J100),"") -> 15.8 | K7: =IF(SUM(K10:K100)>0,SUM(K10:K100),"") -> 11.3
C8: Acumulado Valor Planificado | D8: =IF(D7="","",D7) -> 9.4 | E8: =IF(E7="",D8,E7+D8) -> 17.9 | F8: =IF(F7="",E8,F7+E8) -> 32.1 | G8: =IF(G7="",F8,G7+F8) -> 44.1 | H8: =IF(H7="",G8,H7+G8) -> 52.8 | I8: =IF(I7="",H8,I7+H8) -> 60.4 | J8: =IF(J7="",I8,J7+I8) -> 76.2 | K8: =IF(K7="",J8,K7+J8) -> 87.5
B9: Nombre Tarea | C9: TBC | D9: =Informe!D22 -> S1 | E9: =Informe!E22 -> S2 | F9: =Informe!F22 -> S3 | G9: =Informe!G22 -> S4 | H9: =Informe!H22 -> S5 | I9: =Informe!I22 -> S6 | J9: =Informe!J22 -> S7 | K9: =Informe!K22 -> S8
