Workbook

Sheet Hoja Identificación
A1: Título | B1: Ejemplo de Plan de Calidad
A2: Versión | B2: 0.3h
A3: Lista cambios
A4: C1 | B4: Se ha añadido los datos del proyecto
A5: - | B5: Dentro del proyecto están las fases
A6: - | B6: Dentro de las fases se producen productos
A7: - | B7: Los defectos se agrupan en tipos estandar
A8: C2 | B8: Se ha añadido la hoja lista de defectos
A9: - | B9: Todos los defectos tienen un origen
A10: - | B10: Todos los defectos se detectan en un punto del proceso
A11: - | B11: Todos los defectos se pueden asignar a un tipo para su análisis
A12: - | B12: Todos los defectos se encuentran en un producto
B13: Todos los defectos podemos identificar su ubicación
A14: C3 | B14: Se han corregido campo de valiaciones en la lista de defectos
B15: Se ha añadido el calculo de defectos presentes en cada fase (ver matriz de defectos)
B16: Se ha añadido el calculo del yield de las fases (ver pie matriz de defectos)
B17: Se ha añadido la funcion de calculo de la velocidad de inyeccion de defectos
B18: Se han añadido los costes promedios de reparacion por origen y por punto de deteccion
A19: C4 | B19: Se ha eliminado la hoja prototipo de cuadro de mando
B20: Se ha corregido la formula de densidad de defectos
A21: To do
A22: Falta
A23: F1 | B23: Hacer que un cambio en el nombre de las fases del proyecto se expanda en todas las hojas
A24: F2 | B24: Completar un cuadro de mando con los costes de reparación
A25: F3 | B25: Hay muchas listas que son estáticas seria bueno hacerlas dinámicas

Sheet Ayuda
B1: GENERAL
B2: Los campos con el fondo de color marrón son campos calculados | C2: NO RELLENAR
B3: Los campos de color amarillo son campos de entrada | C3: RELLENAR
B6: Pasos
B7: Página "Datos proyecto"
A8: 1. | B8: Introducir la estimación inicial de PF para el ciclo 1 en la celda I4 de la pagina "Datos proyecto"
A9: 2. | B9: Introducir los valores planificados de cada una de las fases en las celdas C8 a C18 de la pagina "Datos Proyecto"
A10: 3. | B10: Introducir los valores reales de cada una de las fases en las celdas D8 a D18 en la página "Datos proyecto"
A11: 4. | B11: Introducir los productos generados con sus estimaciones de tamaño y valor actual en las celdas en la página "Datos proyecto"
B12: Página "DefectosFase"
A13: 5. | B13: Introducir los valores estimados de defectos insertados por fase en las celdas c4 a C13
A14: 6. | B14: Introducir los valores estimados de defectos eliminados por fase en las celdas i4 a i14
B15: Página "Estandar defectos"
A16: 7. | B16: Revisar la lista de tipos estandar de defectos y colocar los tipos que se deseen actualizando el Informe de Calidad
B17: Página "Lista defectos"
A18: 8. | B18: Introducir la lista de defectos, teniendo en cuenta que la columna I se genere el código auxiliar necesario para las búsquedas
B19: Página "Plan de calidad"
A20: 9. | B20: Introducir el número de programadores estimado y real en las celdas C6 y D6
B21: Página "Rendimiento"
A22: 10. | B22: Revisar los rendimientos obtenidos
B23: Página "Informe de calidad"
A24: 11. | B24: Revisar la información generada

Sheet Datos proyecto
A1: Datos generales del proyecto
B2: Ciclo 2
C3: Planificado | D3: Real
B4: Esfuerzo Total | C4: =SUM(C8:C18) -> 20.5 | D4: =SUM(D8:D18) -> 42.7 | G4: Estimación preliminar de tamaño | I4: 26 | J4: Puntos Funcion
G5: Estimación de LOC | I5: =SUMIF(J$8:J$80,"LOC",H$8:H$80) -> 1500
C6: Esfuerzo
B7: Fases del proyecto C2 | C7: Planificado | D7: Real | F7: en esta fase generó | G7: este producto | H7: tamaño planificado | I7: con este tamaño | J7: unidad de tamaño | K7: Código Auxiliar
A8: DESARROLLO | B8: Lanzamiento | C8: 2.5 | D8: 2.5 | F8: Requisitos | G8: Documento de ERS | H8: 2 | I8: 4 | J8: paginas de texto | K8: =F8&J8 -> Requisitospaginas de texto
B9: Requisitos | C9: 0 | D9: 0 | F9: Estrategia | G9: Documento de Estimación y Planificación | H9: 10 | I9: 12 | J9: paginas de texto | K9: =F9&J9 -> Estrategiapaginas de texto
B10: Inspección de Requisitos | C10: 0.2 | D10: 4 | F10: Estrategia | G10: Documento de Inspección de DEPPF | H10: 1 | I10: 1 | J10: paginas de texto | K10: Estrategiapaginas de texto
B11: Estrategia | C11: 1.2 | D11: 4.2 | F11: Estrategia | G11: Documento de Inspección de DEPPF | H11: 1 | I11: 1 | J11: paginas de texto | K11: Estrategiapaginas de texto
B12: Planificación | C12: 1.4 | D12: 3 | F12: Planificación | G12: Diagrama de Gantt | H12: 30 | I12: 32 | J12: tareas | K12: =F12&J12 -> Planificacióntareas
B13: Diseño | C13: 0.8 | D13: 2.5 | F13: Planificación | G13: Plan de Gestión de Configuración Software | H13: 3 | I13: 3 | J13: paginas de texto | K13: =F13&J13 -> Planificaciónpaginas de texto
B14: Inspección de diseño | C14: 0.5 | D14: 1.1 | F14: Planificación | G14: Documento de Inspección de PGCS | H14: 1 | I14: 1 | J14: paginas de texto | K14: =F14&J14 -> Planificaciónpaginas de texto
B15: Código | C15: 1.3 | D15: 7.9 | F15: Diseño | G15: Diagrama de secuencias | H15: 2 | I15: 3 | J15: interacciones | K15: =F15&J15 -> Diseñointeracciones
B16: Revisión de código | C16: 1.6 | D16: 3.8 | F16: Diseño | G16: Prototipo de pantallas | H16: 2 | I16: 3 | J16: elementos de diseño | K16: =F16&J16 -> Diseñoelementos de diseño
B17: Pruebas | C17: 0.6 | D17: 1 | F17: Diseño | G17: Documento de diseño | H17: 3 | I17: 3 | J17: paginas de texto | K17: =F17&J17 -> Diseñopaginas de texto
B18: Gestión y miscelaneas | C18: 10.4 | D18: 12.7 | F18: Diseño | G18: Documento de Inspección del Diseño | H18: 1 | I18: 1 | J18: paginas de texto | K18: =F18&J18 -> Diseñopaginas de texto
F19: Código | G19: Código Fuente | H19: 1500 | I19: 1637 | J19: LOC | K19: =F19&J19 -> CódigoLOC
F20: Código | G20: Documento de Inspección del Código Fuente | H20: 1 | I20: 1 | J20: paginas de texto | K20: =F20&J20 -> Códigopaginas de texto
F21: Pruebas | G21: Casos de Pruebas Unitarias | H21: 10 | I21: 6 | J21: elementos de prueba | K21: =F21&J21 -> Pruebaselementos de prueba
F22: Pruebas | G22: Casos de Pruebas del Sistema | H22: 2 | I22: 2 | J22: elementos de prueba | K22: =F22&J22 -> Pruebaselementos de prueba
F23: Pruebas | G23: Informe de tests | H23: 2 | I23: 3 | J23: paginas de texto | K23: =F23&J23 -> Pruebaspaginas de texto
K28: =F28&J28
K29: =F29&J29
K30: =F30&J30
K31: =F31&J31
K32: =F32&J32
K33: =F33&J33
K34: =F34&J34
K35: =F35&J35
K36: =F36&J36
K37: =F37&J37
K38: =F38&J38

Sheet DefectosFase
A1: Medidas de Defectos introducidos y eliminados por fase
A3: Defectos insertados en fase: | C3: Planificados | D3: Real | G3: Valor Referencia | J3: Defectos eliminados en fase: | L3: Planificados | M3: Real | P3: Valor Referencia
B4: ='Datos proyecto'!B8 -> Lanzamiento | C4: 1 | D4: =COUNTIF('Lista defectos'!$B$3:B$303,B4) -> 0 | G4: =G19*'Datos proyecto'!C8 -> 0.625 | K4: ='Datos proyecto'!B8 -> Lanzamiento | L4: 1 | M4: =COUNTIF('Lista defectos'!$C$3:$C$303,$B4) -> 0
B5: ='Datos proyecto'!B9 -> Requisitos | C5: 0 | D5: =COUNTIF('Lista defectos'!$B$3:B$303,B5) -> 0 | K5: ='Datos proyecto'!B9 -> Requisitos | L5: 0 | M5: =COUNTIF('Lista defectos'!$C$3:$C$303,$B5) -> 0 | P5: =P20*'Datos proyecto'!C9 -> 0
B6: ='Datos proyecto'!B10 -> Inspección de Requisitos | C6: 0 | D6: =COUNTIF('Lista defectos'!$B$3:B$303,B6) -> 0 | G6: =G21*'Datos proyecto'!C10 -> 0.05 | K6: ='Datos proyecto'!B10 -> Inspección de Requisitos | L6: 0 | M6: =COUNTIF('Lista defectos'!$C$3:$C$303,$B6) -> 0
B7: ='Datos proyecto'!B11 -> Estrategia | C7: 1 | D7: =COUNTIF('Lista defectos'!$B$3:B$303,B7) -> 0 | K7: ='Datos proyecto'!B11 -> Estrategia | L7: 1 | M7: =COUNTIF('Lista defectos'!$C$3:$C$303,$B7) -> 0 | P7: =P22*'Datos proyecto'!C11 -> 0.6
B8: ='Datos proyecto'!B12 -> Planificación | C8: 2 | D8: =COUNTIF('Lista defectos'!$B$3:B$303,B8) -> 0 | G8: =G23*'Datos proyecto'!C12 -> 2.8 | K8: ='Datos proyecto'!B12 -> Planificación | L8: 2 | M8: =COUNTIF('Lista defectos'!$C$3:$C$303,$B8) -> 0
B9: ='Datos proyecto'!B13 -> Diseño | C9: 2 | D9: =COUNTIF('Lista defectos'!$B$3:B$303,B9) -> 0 | K9: ='Datos proyecto'!B13 -> Diseño | L9: 0 | M9: =COUNTIF('Lista defectos'!$C$3:$C$303,$B9) -> 0 | P9: =P24*'Datos proyecto'!C13 -> 1.6
B10: ='Datos proyecto'!B14 -> Inspección de diseño | C10: 0 | D10: =COUNTIF('Lista defectos'!$B$3:B$303,B10) -> 0 | G10: =G25*'Datos proyecto'!C14 -> 2 | K10: ='Datos proyecto'!B14 -> Inspección de diseño | L10: 2 | M10: =COUNTIF('Lista defectos'!$C$3:$C$303,$B10) -> 0
B11: ='Datos proyecto'!B15 -> Código | C11: 10 | D11: =COUNTIF('Lista defectos'!$B$3:B$303,B11) -> 2 | K11: ='Datos proyecto'!B15 -> Código | L11: 6 | M11: =COUNTIF('Lista defectos'!$C$3:$C$303,$B11) -> 0 | P11: =P26*'Datos proyecto'!C15 -> 7.8
B12: ='Datos proyecto'!B16 -> Revisión de código | C12: 0 | D12: =COUNTIF('Lista defectos'!$B$3:B$303,B12) -> 0 | G12: =G27*'Datos proyecto'!C16 -> 0.32 | K12: ='Datos proyecto'!B16 -> Revisión de código | L12: 3 | M12: =COUNTIF('Lista defectos'!$C$3:$C$303,$B12) -> 1
B13: ='Datos proyecto'!B17 -> Pruebas | C13: 0 | D13: =COUNTIF('Lista defectos'!$B$3:B$303,B13) -> 0 | K13: ='Datos proyecto'!B17 -> Pruebas | L13: 1 | M13: =COUNTIF('Lista defectos'!$C$3:$C$303,$B13) -> 1
B14: Total | C14: =SUM(C4:C13) -> 16 | D14: =SUM(D4:D13) -> 2 | K14: Total | L14: =SUM(L4:L13) -> 16 | M14: =SUM(M4:M13) -> 2
A18: Velocidad de inserción en cada fase(def/hora) | C18: Planificada | D18: Real | G18: Valor Referencia | J18: Velocidad de eliminación en cada fase | L18: Planificada | M18: Real | P18: Valor Referencia
B19: ='Datos proyecto'!$B8 -> Lanzamiento | C19: =IFERROR(C4/'Datos proyecto'!C8,0) -> 0.4 | D19: =IFERROR(D4/'Datos proyecto'!D8,0) -> 0 | E19: def/hora | G19: 0.25 | K19: ='Datos proyecto'!$B8 -> Lanzamiento | L19: =IFERROR(L4/'Datos proyecto'!C8,0) -> 0.4 | M19: =IFERROR(M4/'Datos proyecto'!D8,0) -> 0 | N19: def/hora
B20: ='Datos proyecto'!$B9 -> Requisitos | C20: =IFERROR(C5/'Datos proyecto'!C9,0) -> 0 | D20: =IFERROR(D5/'Datos proyecto'!D9,0) -> 0 | E20: def/hora | K20: ='Datos proyecto'!$B9 -> Requisitos | L20: =IFERROR(L5/'Datos proyecto'!C9,0) -> 0 | M20: =IFERROR(M5/'Datos proyecto'!D9,0) -> 0 | N20: def/hora | P20: 0.5
B21: ='Datos proyecto'!$B10 -> Inspección de Requisitos | C21: =IFERROR(C6/'Datos proyecto'!C10,0) -> 0 | D21: =IFERROR(D6/'Datos proyecto'!D10,0) -> 0 | E21: def/hora | G21: 0.25 | K21: ='Datos proyecto'!$B10 -> Inspección de Requisitos | L21: =IFERROR(L6/'Datos proyecto'!C10,0) -> 0 | M21: =IFERROR(M6/'Datos proyecto'!D10,0) -> 0 | N21: def/hora
B22: ='Datos proyecto'!$B11 -> Estrategia | C22: =IFERROR(C7/'Datos proyecto'!C11,0) -> 0.83333333 | D22: =IFERROR(D7/'Datos proyecto'!D11,0) -> 0 | E22: def/hora | K22: ='Datos proyecto'!$B11 -> Estrategia | L22: =IFERROR(L7/'Datos proyecto'!C11,0) -> 0.83333333 | M22: =IFERROR(M7/'Datos proyecto'!D11,0) -> 0 | N22: def/hora | P22: 0.5
B23: ='Datos proyecto'!$B12 -> Planificación | C23: =IFERROR(C8/'Datos proyecto'!C12,0) -> 1.4285714 | D23: =IFERROR(D8/'Datos proyecto'!D12,0) -> 0 | E23: def/hora | G23: 2 | K23: ='Datos proyecto'!$B12 -> Planificación | L23: =IFERROR(L8/'Datos proyecto'!C12,0) -> 1.4285714 | M23: =IFERROR(M8/'Datos proyecto'!D12,0) -> 0 | N23: def/hora
B24: ='Datos proyecto'!$B13 -> Diseño | C24: =IFERROR(C9/'Datos proyecto'!C13,0) -> 2.5 | D24: =IFERROR(D9/'Datos proyecto'!D13,0) -> 0 | E24: def/hora | K24: ='Datos proyecto'!$B13 -> Diseño | L24: =IFERROR(L9/'Datos proyecto'!C13,0) -> 0 | M24: =IFERROR(M9/'Datos proyecto'!D13,0) -> 0 | N24: def/hora | P24: 2
B25: ='Datos proyecto'!$B14 -> Inspección de diseño | C25: =IFERROR(C10/'Datos proyecto'!C14,0) -> 0 | D25: =IFERROR(D10/'Datos proyecto'!D14,0) -> 0 | E25: def/hora | G25: 4 | K25: ='Datos proyecto'!$B14 -> Inspección de diseño | L25: =IFERROR(L10/'Datos proyecto'!C14,0) -> 4 | M25: =IFERROR(M10/'Datos proyecto'!D14,0) -> 0 | N25: def/hora
B26: ='Datos proyecto'!$B15 -> Código | C26: =IFERROR(C11/'Datos proyecto'!C15,0) -> 7.6923077 | D26: =IFERROR(D11/'Datos proyecto'!D15,0) -> 0.25316456 | E26: def/hora | K26: ='Datos proyecto'!$B15 -> Código | L26: =IFERROR(L11/'Datos proyecto'!C15,0) -> 4.6153846 | M26: =IFERROR(M11/'Datos proyecto'!D15,0) -> 0 | N26: def/hora | P26: 6
B27: ='Datos proyecto'!$B16 -> Revisión de código | C27: =IFERROR(C12/'Datos proyecto'!C16,0) -> 0 | D27: =IFERROR(D12/'Datos proyecto'!D16,0) -> 0 | E27: def/hora | G27: 0.2 | K27: ='Datos proyecto'!$B16 -> Revisión de código | L27: =IFERROR(L12/'Datos proyecto'!C16,0) -> 1.875 | M27: =IFERROR(M12/'Datos proyecto'!D16,0) -> 0.26315789 | N27: def/hora
B28: ='Datos proyecto'!$B17 -> Pruebas | C28: =IFERROR(C13/'Datos proyecto'!C17,0) -> 0 | D28: =IFERROR(D13/'Datos proyecto'!D17,0) -> 0 | E28: def/hora | K28: ='Datos proyecto'!$B17 -> Pruebas | L28: =IFERROR(L13/'Datos proyecto'!C17,0) -> 1.6666667 | M28: =IFERROR(M13/'Datos proyecto'!D17,0) -> 1 | N28: def/hora

Sheet Estandar defectos
A1: Tipos ODC (Orthogonal Defect Classification) Defecto | B1: Descripción
A2: Documentación | B2: Errores en el contenido, descripción y comentarios en los productos
A3: Sintaxis | B3: Errores de escritura en diagramas o código
A4: Configuración | B4: Errores al empaquetar, control de versiones
A5: Asignaciones | B5: Errores en el alcance o nombres duplicados, limites, declaraciones, al inicio y al final de uso de recursos
A6: Interface | B6: Errores en las llamadas y referencias, entrada/salida, formatos para entrada y salidas dirigidas al usuario
A7: Comprobación | B7: Errores por no comprobar errores, o comprobacion no adecuada, mensajes de error
A8: Datos | B8: Errores en la estructura o el contenido de los datos
A9: Funciones | B9: Errores en los limites de los bucles, en la lógica de las funciones, en manejo de punteros, recursividad
A10: Estandar | B10: Cumplimiento de estandares
A11: Entorno | B11: Problemas con el entorno de desarrollo utilizado

Sheet Lista defectos
A1: Lista de defectos
A2: Producto | B2: Origen | C2: Detectado | D2: Esfuerzo Dedicado a reparar | E2: Tipo Estandar | F2: Ubicación (parrafo, Linea u otro elemento que sirva para ubicar) | G2: Descripción | I2: CodigoAuxiliar
A3: Código Fuente | B3: Código | C3: Revisión de código | D3: 0.42 | E3: Sintaxis | F3: 1240 | G3: Falta visualización locales | I3: =B3&C3 -> CódigoRevisión de código
A4: Código Fuente | B4: Código | C4: Pruebas | D4: 0.03 | E4: Sintaxis | F4: 406 | G4: Errata en texto aplicación | I4: =B4&C4 -> CódigoPruebas
I5: =B5&C5
I6: =B6&C6
I7: =B7&C7
I8: =B8&C8
I9: =B9&C9
I10: =B10&C10
I11: =B11&C11
I12: =B12&C12
I13: =B13&C13
I14: =B14&C14
I15: =B15&C15
I16: =B16&C16
... I337: =B337&C337

Sheet Plan Calidad
A1: Plan de calidad
A2: Volumenes
B3: LOC | C3: =SUMIF('Datos proyecto'!J8:J$80,"LOC",'Datos proyecto'!H8:H$80) -> 1500 | D3: =SUMIF('Datos proyecto'!J8:J$80,"LOC",'Datos proyecto'!I8:I$80) -> 1637
A4: Tasas resumen | C4: Plan | D4: Real
B5: LOC/hora | C5: =$C$3/'Datos proyecto'!C4 -> 73.170732 | D5: =$D$3/'Datos proyecto'!D4 -> 38.337237
B6: Número programadores | C6: 5 | D6: 5
A8: Defectos por página
B9: Inspeccion de requisitos | C9: =IFERROR(DefectosFase!L5/SUMIF('Datos proyecto'!$K$8:$K$80,"Requisitospaginas de texto",'Datos proyecto'!H$8:H$80),"") -> 0 | D9: =IFERROR(DefectosFase!M5/SUMIF('Datos proyecto'!$K$8:$K$80,"Requisitospaginas de texto",'Datos proyecto'!I$8:I$80),"") -> 0
B10: Inspección de diseño | C10: =IFERROR(DefectosFase!L7/SUMIF('Datos proyecto'!$K$8:$K$80,"Diseñopaginas de texto",'Datos proyecto'!H$8:H$80),"") -> 0.25 | D10: =IFERROR(DefectosFase!M7/SUMIF('Datos proyecto'!$K$8:$K$80,"Diseñopaginas de texto",'Datos proyecto'!I$8:I$80),"") -> 0
A11: Defectos por KLOC
B12: Revision Diseño detallado | C12: =DefectosFase!L9/'Plan Calidad'!$C$3*1000 -> 0 | D12: =DefectosFase!M9/'Plan Calidad'!$D$3*1000 -> 0
B13: Revision de código | C13: =DefectosFase!L11/'Plan Calidad'!$C$3*1000 -> 4 | D13: =DefectosFase!M11/'Plan Calidad'!$D$3*1000 -> 0
B14: Pruebas Unitarias | C14: =DefectosFase!L12/'Plan Calidad'!$C$3*1000 -> 2 | D14: =DefectosFase!M12/'Plan Calidad'!$D$3*1000 -> 0.61087355
B15: Pruebas Sistema | C15: =DefectosFase!L13/'Plan Calidad'!$C$3*1000 -> 0.66666667 | D15: =DefectosFase!M13/'Plan Calidad'!$D$3*1000 -> 0.61087355
A16: Ratios de defectos
B17: Revisión Diseño Detallado vs Pruebas Unitarias | C17: =IFERROR(DefectosFase!L9/DefectosFase!L12,"") -> 0 | D17: =IFERROR(DefectosFase!M9/DefectosFase!M12,"") -> 0
A18: Ratios de tiempos de desarrollo
B19: Inspecciones requisitos/Requisitos | C19: =IFERROR('Datos proyecto'!C9/'Datos proyecto'!C8,"") -> 0 | D19: =IFERROR('Datos proyecto'!D9/'Datos proyecto'!D8,"") -> 0
B20: Inspección de diseño alto nivel/Diseño | C20: =IFERROR('Datos proyecto'!C11/'Datos proyecto'!C10,"") -> 6 | D20: =IFERROR('Datos proyecto'!D11/'Datos proyecto'!D10,"") -> 1.05
B21: Diseño detallado/Código | C21: =IFERROR('Datos proyecto'!C12/'Datos proyecto'!C14,"") -> 2.8 | D21: =IFERROR('Datos proyecto'!D12/'Datos proyecto'!D14,"") -> 2.7272727
A23: Velocidades de revision
B24: Lineas de Diseño detallado/hora | C24: =IFERROR(SUMIF('Datos proyecto'!$K$8:$K$80,"Diseño detalladolineas pseudocódigo",'Datos proyecto'!H$8:H$80)/'Datos proyecto'!C13,"") -> 0 | D24: =IFERROR(SUMIF('Datos proyecto'!$K$8:$K$80,"Diseño detalladolineas pseudocódigo",'Datos proyecto'!I$8:I$80)/'Datos proyecto'!D13,"") -> 0
B25: LOCcódigo/hora | C25: =IFERROR(SUMIF('Datos proyecto'!$K$8:$K$80,"CódigoLOC",'Datos proyecto'!H$8:H$80)/'Datos proyecto'!C14,"") -> 3000 | D25: =IFERROR(SUMIF('Datos proyecto'!$K$8:$K$80,"CódigoLOC",'Datos proyecto'!I$8:I$80)/'Datos proyecto'!D14,"") -> 1488.1818
A26: Tasas de injección (def/hora)
B27: Requisitos | C27: =IFERROR(DefectosFase!C4/'Datos proyecto'!C8,"") -> 0.4 | D27: =IFERROR(DefectosFase!D4/'Datos proyecto'!D8,"") -> 0
B28: Diseño Alto Nivel | C28: =IFERROR(DefectosFase!C6/'Datos proyecto'!C10,"") -> 0 | D28: =IFERROR(DefectosFase!D6/'Datos proyecto'!D10,"") -> 0
B29: Diseño Detallado | C29: =IFERROR(DefectosFase!C8/'Datos proyecto'!C12,"") -> 1.4285714 | D29: =IFERROR(DefectosFase!D8/'Datos proyecto'!D12,"") -> 0
B30: Código | C30: =IFERROR(DefectosFase!C10/'Datos proyecto'!C14,"") -> 0 | D30: =IFERROR(DefectosFase!D10/'Datos proyecto'!D14,"") -> 0
A32: Tasas de eliminación (def/hora)
B33: Inspección requisitos | C33: =IFERROR(DefectosFase!L5/'Datos proyecto'!C9,"") | D33: =IFERROR(DefectosFase!M5/'Datos proyecto'!D9,"")
B34: Inspección de Diseño alto nivel | C34: =IFERROR(DefectosFase!L7/'Datos proyecto'!C11,"") -> 0.83333333 | D34: =IFERROR(DefectosFase!M7/'Datos proyecto'!D11,"") -> 0
B35: Revisión Diseño Detallado | C35: =IFERROR(DefectosFase!L8/'Datos proyecto'!C13,"") -> 2.5 | D35: =IFERROR(DefectosFase!M8/'Datos proyecto'!D13,"") -> 0
B36: Revisión de código | C36: =IFERROR(DefectosFase!L11/'Datos proyecto'!C15,"") -> 4.6153846 | D36: =IFERROR(DefectosFase!M11/'Datos proyecto'!D15,"") -> 0
B37: Pruebas Unitarias | C37: =IFERROR(DefectosFase!L12/'Datos proyecto'!C16,"") -> 1.875 | D37: =IFERROR(DefectosFase!M12/'Datos proyecto'!D16,"") -> 0.26315789
B38: Pruebas del sistema | C38: =IFERROR(DefectosFase!L13/'Datos proyecto'!C17,"") -> 1.6666667 | D38: =IFERROR(DefectosFase!M13/'Datos proyecto'!D17,"") -> 1
A40: Rendimiento fases eliminación
B41: Inpección requisitos | D41: =Rendimiento!R5
B42: Inspección Diseño Alto Nivel | D42: =Rendimiento!R7
B43: Revisión Diseño detallado | D43: =Rendimiento!R9
B44: Revisión de código | D44: =Rendimiento!R10
...

Sheet Rendimiento
A1: Tabla de rendimientos
B3: Fase | D3: ='Datos proyecto'!B8 -> Lanzamiento | E3: ='Datos proyecto'!B9 -> Requisitos | F3: ='Datos proyecto'!B10 -> Inspección de Requisitos | G3: ='Datos proyecto'!B11 -> Estrategia | H3: ='Datos proyecto'!B12 -> Planificación | I3: ='Datos proyecto'!B13 -> Diseño | J3: ='Datos proyecto'!B14 -> Inspección de diseño | K3: ='Datos proyecto'!B15 -> Código | L3: ='Datos proyecto'!B16 -> Revisión de código | M3: ='Datos proyecto'!B17 -> Pruebas | N3: Defectos introducidos | O3: Presentes | P3: Eliminados | Q3: escapados | R3: Rendimiento | S3: Coste reparación | T3: Coste promedio
C4: ='Datos proyecto'!B8 -> Lanzamiento | D4: =COUNTIFS('Lista defectos'!$B:$B,$C4,'Lista defectos'!$C:$C,D$3) -> 0 | E4: =COUNTIFS('Lista defectos'!$B:$B,$C4,'Lista defectos'!$C:$C,E$3) -> 0 | F4: =COUNTIFS('Lista defectos'!$B:$B,$C4,'Lista defectos'!$C:$C,F$3) -> 0 | G4: =COUNTIFS('Lista defectos'!$B:$B,$C4,'Lista defectos'!$C:$C,G$3) -> 0 | H4: =COUNTIFS('Lista defectos'!$B:$B,$C4,'Lista defectos'!$C:$C,H$3) -> 0 | I4: =COUNTIFS('Lista defectos'!$B:$B,$C4,'Lista defectos'!$C:$C,I$3) -> 0 | J4: =COUNTIFS('Lista defectos'!$B:$B,$C4,'Lista defectos'!$C:$C,J$3) -> 0 | K4: =COUNTIFS('Lista defectos'!$B:$B,$C4,'Lista defectos'!$C:$C,K$3) -> 0 | ... M4: =COUNTIFS('Lista defectos'!$B:$B,$C4,'Lista defectos'!$C:$C,M$3) -> 0 | N4: =SUM(D4:M4) -> 0 | O4: =N4 -> 0 | P4: =DefectosFase!M4 -> 0 | Q4: =O4-P4 -> 0 | R4: =IFERROR(P4/O4,"") | S4: =SUMIF('Lista defectos'!$B$3:$B$400,C4,'Lista defectos'!$D$3:D$400) -> 0 | T4: =IF(N4=0,"",AVERAGEIF('Lista defectos'!$B$3:$B$400,C4,'Lista defectos'!$D$3:E$400))
C5: ='Datos proyecto'!B9 -> Requisitos | E5: =COUNTIFS('Lista defectos'!$B:$B,$C5,'Lista defectos'!$C:$C,E$3) -> 0 | F5: =COUNTIF('Lista defectos'!$I$3:$I$91,$C$5&F$3) -> 0 | G5: =COUNTIFS('Lista defectos'!$B:$B,$C5,'Lista defectos'!$C:$C,G$3) -> 0 | H5: =COUNTIFS('Lista defectos'!$B:$B,$C5,'Lista defectos'!$C:$C,H$3) -> 0 | I5: =COUNTIFS('Lista defectos'!$B:$B,$C5,'Lista defectos'!$C:$C,I$3) -> 0 | J5: =COUNTIFS('Lista defectos'!$B:$B,$C5,'Lista defectos'!$C:$C,J$3) -> 0 | K5: =COUNTIFS('Lista defectos'!$B:$B,$C5,'Lista defectos'!$C:$C,K$3) -> 0 | L5: =COUNTIFS('Lista defectos'!$B:$B,$C5,'Lista defectos'!$C:$C,L$3) -> 0 | M5: =COUNTIFS('Lista defectos'!$B:$B,$C5,'Lista defectos'!$C:$C,M$3) -> 0 | N5: =SUM(D5:M5) -> 0 | O5: =N5+Q4 -> 0 | P5: =DefectosFase!M5 -> 0 | Q5: =O5-P5 -> 0 | R5: =IFERROR(P5/O5,"") | S5: =SUMIF('Lista defectos'!$B$3:$B$400,C5,'Lista defectos'!$D$3:D$400) -> 0 | T5: =IF(N5=0,"",AVERAGEIF('Lista defectos'!$B$3:$B$400,C5,'Lista defectos'!$D$3:E$400))
C6: ='Datos proyecto'!B10 -> Inspección de Requisitos | F6: =COUNTIF('Lista defectos'!$I$3:$I$91,$C$6&F$3) -> 0 | G6: =COUNTIFS('Lista defectos'!$B:$B,$C6,'Lista defectos'!$C:$C,G$3) -> 0 | H6: =COUNTIFS('Lista defectos'!$B:$B,$C6,'Lista defectos'!$C:$C,H$3) -> 0 | I6: =COUNTIFS('Lista defectos'!$B:$B,$C6,'Lista defectos'!$C:$C,I$3) -> 0 | J6: =COUNTIFS('Lista defectos'!$B:$B,$C6,'Lista defectos'!$C:$C,J$3) -> 0 | K6: =COUNTIFS('Lista defectos'!$B:$B,$C6,'Lista defectos'!$C:$C,K$3) -> 0 | L6: =COUNTIFS('Lista defectos'!$B:$B,$C6,'Lista defectos'!$C:$C,L$3) -> 0 | M6: =COUNTIFS('Lista defectos'!$B:$B,$C6,'Lista defectos'!$C:$C,M$3) -> 0 | N6: =SUM(D6:M6) -> 0 | O6: =N6+Q5 -> 0 | P6: =DefectosFase!M6 -> 0 | Q6: =O6-P6 -> 0 | R6: =IFERROR(P6/O6,"") | S6: =SUMIF('Lista defectos'!$B$3:$B$400,C6,'Lista defectos'!$D$3:D$400) -> 0 | T6: =IF(N6=0,"",AVERAGEIF('Lista defectos'!$B$3:$B$400,C6,'Lista defectos'!$D$3:E$400))
C7: ='Datos proyecto'!B11 -> Estrategia | G7: =COUNTIFS('Lista defectos'!$B:$B,$C7,'Lista defectos'!$C:$C,G$3) -> 0 | H7: =COUNTIFS('Lista defectos'!$B:$B,$C7,'Lista defectos'!$C:$C,H$3) -> 0 | I7: =COUNTIFS('Lista defectos'!$B:$B,$C7,'Lista defectos'!$C:$C,I$3) -> 0 | J7: =COUNTIFS('Lista defectos'!$B:$B,$C7,'Lista defectos'!$C:$C,J$3) -> 0 | K7: =COUNTIFS('Lista defectos'!$B:$B,$C7,'Lista defectos'!$C:$C,K$3) -> 0 | L7: =COUNTIFS('Lista defectos'!$B:$B,$C7,'Lista defectos'!$C:$C,L$3) -> 0 | M7: =COUNTIFS('Lista defectos'!$B:$B,$C7,'Lista defectos'!$C:$C,M$3) -> 0 | N7: =SUM(D7:M7) -> 0 | O7: =N7+Q6 -> 0 | P7: =DefectosFase!M7 -> 0 | Q7: =O7-P7 -> 0 | R7: =IFERROR(P7/O7,"") | S7: =SUMIF('Lista defectos'!$B$3:$B$400,C7,'Lista defectos'!$D$3:D$400) -> 0 | T7: =IF(N7=0,"",AVERAGEIF('Lista defectos'!$B$3:$B$400,C7,'Lista defectos'!$D$3:E$400))
C8: ='Datos proyecto'!B12 -> Planificación | H8: =COUNTIFS('Lista defectos'!$B:$B,$C8,'Lista defectos'!$C:$C,H$3) -> 0 | I8: =COUNTIFS('Lista defectos'!$B:$B,$C8,'Lista defectos'!$C:$C,I$3) -> 0 | J8: =COUNTIFS('Lista defectos'!$B:$B,$C8,'Lista defectos'!$C:$C,J$3) -> 0 | K8: =COUNTIFS('Lista defectos'!$B:$B,$C8,'Lista defectos'!$C:$C,K$3) -> 0 | L8: =COUNTIFS('Lista defectos'!$B:$B,$C8,'Lista defectos'!$C:$C,L$3) -> 0 | M8: =COUNTIFS('Lista defectos'!$B:$B,$C8,'Lista defectos'!$C:$C,M$3) -> 0 | N8: =SUM(D8:M8) -> 0 | O8: =N8+Q7 -> 0 | P8: =DefectosFase!M8 -> 0 | Q8: =O8-P8 -> 0 | R8: =IFERROR(P8/O8,"") | S8: =SUMIF('Lista defectos'!$B$3:$B$400,C8,'Lista defectos'!$D$3:D$400) -> 0 | T8: =IF(N8=0,"",AVERAGEIF('Lista defectos'!$B$3:$B$400,C8,'Lista defectos'!$D$3:E$400))
C9: ='Datos proyecto'!B13 -> Diseño | I9: =COUNTIFS('Lista defectos'!$B:$B,$C9,'Lista defectos'!$C:$C,I$3) -> 0 | J9: =COUNTIFS('Lista defectos'!$B:$B,$C9,'Lista defectos'!$C:$C,J$3) -> 0 | K9: =COUNTIFS('Lista defectos'!$B:$B,$C9,'Lista defectos'!$C:$C,K$3) -> 0 | L9: =COUNTIFS('Lista defectos'!$B:$B,$C9,'Lista defectos'!$C:$C,L$3) -> 0 | M9: =COUNTIFS('Lista defectos'!$B:$B,$C9,'Lista defectos'!$C:$C,M$3) -> 0 | N9: =SUM(D9:M9) -> 0 | O9: =N9+Q8 -> 0 | P9: =DefectosFase!M9 -> 0 | Q9: =O9-P9 -> 0 | R9: =IFERROR(P9/O9,"") | S9: =SUMIF('Lista defectos'!$B$3:$B$400,C9,'Lista defectos'!$D$3:D$400) -> 0 | T9: =IF(N9=0,"",AVERAGEIF('Lista defectos'!$B$3:$B$400,C9,'Lista defectos'!$D$3:E$400))
C10: ='Datos proyecto'!B14 -> Inspección de diseño | J10: =COUNTIFS('Lista defectos'!$B:$B,$C10,'Lista defectos'!$C:$C,J$3) -> 0 | K10: =COUNTIFS('Lista defectos'!$B:$B,$C10,'Lista defectos'!$C:$C,K$3) -> 0 | L10: =COUNTIFS('Lista defectos'!$B:$B,$C10,'Lista defectos'!$C:$C,L$3) -> 0 | M10: =COUNTIFS('Lista defectos'!$B:$B,$C10,'Lista defectos'!$C:$C,M$3) -> 0 | N10: =SUM(D10:M10) -> 0 | O10: =N10+Q9 -> 0 | P10: =DefectosFase!M10 -> 0 | Q10: =O10-P10 -> 0 | R10: =IFERROR(P10/O10,"") | S10: =SUMIF('Lista defectos'!$B$3:$B$400,C10,'Lista defectos'!$D$3:D$400) -> 0 | T10: =IF(N10=0,"",AVERAGEIF('Lista defectos'!$B$3:$B$400,C10,'Lista defectos'!$D$3:E$400))
C11: ='Datos proyecto'!B15 -> Código | K11: =COUNTIFS('Lista defectos'!$B:$B,$C11,'Lista defectos'!$C:$C,K$3) -> 0 | L11: =COUNTIFS('Lista defectos'!$B:$B,$C11,'Lista defectos'!$C:$C,L$3) -> 1 | M11: =COUNTIFS('Lista defectos'!$B:$B,$C11,'Lista defectos'!$C:$C,M$3) -> 1 | N11: =SUM(D11:M11) -> 2 | O11: =N11+Q10 -> 2 | P11: =DefectosFase!M11 -> 0 | Q11: =O11-P11 -> 2 | R11: =IFERROR(P11/O11,"") -> 0 | S11: =SUMIF('Lista defectos'!$B$3:$B$400,C11,'Lista defectos'!$D$3:D$400) -> 0.45 | T11: =IF(N11=0,"",AVERAGEIF('Lista defectos'!$B$3:$B$400,C11,'Lista defectos'!$D$3:E$400)) -> 0.225
C12: ='Datos proyecto'!B16 -> Revisión de código | L12: =COUNTIFS('Lista defectos'!$B:$B,$C12,'Lista defectos'!$C:$C,L$3) -> 0 | M12: =COUNTIFS('Lista defectos'!$B:$B,$C12,'Lista defectos'!$C:$C,M$3) -> 0 | N12: =SUM(D12:M12) -> 0 | O12: =N12+Q11 -> 2 | P12: =DefectosFase!M12 -> 1 | Q12: =O12-P12 -> 1 | R12: =IFERROR(P12/O12,"") -> 0.5 | S12: =SUMIF('Lista defectos'!$B$3:$B$400,C12,'Lista defectos'!$D$3:D$400) -> 0 | T12: =IF(N12=0,"",AVERAGEIF('Lista defectos'!$B$3:$B$400,C12,'Lista defectos'!$D$3:E$400))
C13: ='Datos proyecto'!B17 -> Pruebas | M13: =COUNTIFS('Lista defectos'!$B:$B,$C13,'Lista defectos'!$C:$C,M$3) -> 0 | N13: =SUM(D13:M13) -> 0 | O13: =N13+Q12 -> 1 | P13: =DefectosFase!M13 -> 1 | Q13: =O13-P13 -> 0 | R13: =IFERROR(P13/O13,"") -> 1 | S13: =SUMIF('Lista defectos'!$B$3:$B$400,C13,'Lista defectos'!$D$3:D$400) -> 0 | T13: =IF(N13=0,"",AVERAGEIF('Lista defectos'!$B$3:$B$400,C13,'Lista defectos'!$D$3:E$400))
C14: Defectos reparados | D14: =SUM(D4:D13) -> 0 | E14: =SUM(E4:E13) -> 0 | F14: =SUM(F4:F13) -> 0 | G14: =SUM(G4:G13) -> 0 | H14: =SUM(H4:H13) -> 0 | I14: =SUM(I4:I13) -> 0 | J14: =SUM(J4:J13) -> 0 | K14: =SUM(K4:K13) -> 0 | ... M14: =SUM(M4:M13) -> 1
C15: Coste de reparación | D15: =SUMIF('Lista defectos'!$C$3:$C$400,D3,'Lista defectos'!$D$3:D$400) -> 0 | E15: =SUMIF('Lista defectos'!$C$3:$C$400,E3,'Lista defectos'!$D$3:E$400) -> 0 | F15: =SUMIF('Lista defectos'!$C$3:$C$400,F3,'Lista defectos'!$D$3:F$400) -> 0 | G15: =SUMIF('Lista defectos'!$C$3:$C$400,G3,'Lista defectos'!$D$3:G$400) -> 0 | H15: =SUMIF('Lista defectos'!$C$3:$C$400,H3,'Lista defectos'!$D$3:H$400) -> 0 | I15: =SUMIF('Lista defectos'!$C$3:$C$400,I3,'Lista defectos'!$D$3:I$400) -> 0 | J15: =SUMIF('Lista defectos'!$C$3:$C$400,J3,'Lista defectos'!$D$3:J$400) -> 0 | K15: =SUMIF('Lista defectos'!$C$3:$C$400,K3,'Lista defectos'!$D$3:K$400) -> 0 | ... M15: =SUMIF('Lista defectos'!$C$3:$C$400,M3,'Lista defectos'!$D$3:M$400) -> 0.03
C16: Promedio de costes | D16: =IF(D14=0,"",AVERAGEIF('Lista defectos'!$C$3:$C$400,D3,'Lista defectos'!$D$3:D$400)) | E16: =IF(E14=0,"",AVERAGEIF('Lista defectos'!$C$3:$C$400,E3,'Lista defectos'!$D$3:E$400)) | F16: =IF(F14=0,"",AVERAGEIF('Lista defectos'!$C$3:$C$400,F3,'Lista defectos'!$D$3:F$400)) | G16: =IF(G14=0,"",AVERAGEIF('Lista defectos'!$C$3:$C$400,G3,'Lista defectos'!$D$3:G$400)) | H16: =IF(H14=0,"",AVERAGEIF('Lista defectos'!$C$3:$C$400,H3,'Lista defectos'!$D$3:H$400)) | I16: =IF(I14=0,"",AVERAGEIF('Lista defectos'!$C$3:$C$400,I3,'Lista defectos'!$D$3:I$400)) | J16: =IF(J14=0,"",AVERAGEIF('Lista defectos'!$C$3:$C$400,J3,'Lista defectos'!$D$3:J$400)) | K16: =IF(K14=0,"",AVERAGEIF('Lista defectos'!$C$3:$C$400,K3,'Lista defectos'!$D$3:K$400)) | ... M16: =IF(M14=0,"",AVERAGEIF('Lista defectos'!$C$3:$C$400,M3,'Lista defectos'!$D$3:M$400)) -> 0.03

Sheet Informe Calidad
A1: Informe Resultado de calidad
A4: Tamaño proyecto LOC | B4: =SUMIF('Datos proyecto'!$J$8:$J$100,C4,'Datos proyecto'!I$8:I$100) -> 1637 | C4: LOC
A5: Total defectos | B5: =DefectosFase!D14 -> 2 | C5: defectos
A7: Densidad de defectos
A9: Total proyecto | B9: =DefectosFase!D14/B4*1000 -> 1.2217471 | C9: def/KLOC
A10: Total post diseño | B10: =SUM(DefectosFase!M10:M13)/B4*1000 -> 1.2217471 | C10: def/KLOC
A13: Rendimiento de las fases | B13: Yield | D13: Cuanto reparamos en la fase | E13: nos cuesta | H13: Cuando insertamos un defecto en la fase | I13: nos cuesta
A14: ='Datos proyecto'!B8 -> Lanzamiento | B14: =Rendimiento!R4 | D14: ='Datos proyecto'!B8 -> Lanzamiento | E14: =Rendimiento!D$16 | F14: =IF(E14="","","horas") | H14: ='Datos proyecto'!B8 -> Lanzamiento | I14: =Rendimiento!T4 | J14: =IF(I14="","","horas")
A15: ='Datos proyecto'!B9 -> Requisitos | B15: =Rendimiento!R5 | D15: ='Datos proyecto'!B9 -> Requisitos | E15: =Rendimiento!E$16 | F15: =IF(E15="","","horas") | H15: ='Datos proyecto'!B9 -> Requisitos | I15: =Rendimiento!T5 | J15: =IF(I15="","","horas")
A16: ='Datos proyecto'!B10 -> Inspección de Requisitos | B16: =Rendimiento!R6 | D16: ='Datos proyecto'!B10 -> Inspección de Requisitos | E16: =Rendimiento!F$16 | F16: =IF(E16="","","horas") | H16: ='Datos proyecto'!B10 -> Inspección de Requisitos | I16: =Rendimiento!T6 | J16: =IF(I16="","","horas")
A17: ='Datos proyecto'!B11 -> Estrategia | B17: =Rendimiento!R7 | D17: ='Datos proyecto'!B11 -> Estrategia | E17: =Rendimiento!G$16 | F17: =IF(E17="","","horas") | H17: ='Datos proyecto'!B11 -> Estrategia | I17: =Rendimiento!T7 | J17: =IF(I17="","","horas")
A18: ='Datos proyecto'!B12 -> Planificación | B18: =Rendimiento!R8 | D18: ='Datos proyecto'!B12 -> Planificación | E18: =Rendimiento!H$16 | F18: =IF(E18="","","horas") | H18: ='Datos proyecto'!B12 -> Planificación | I18: =Rendimiento!T8 | J18: =IF(I18="","","horas")
A19: ='Datos proyecto'!B13 -> Diseño | B19: =Rendimiento!R9 | D19: ='Datos proyecto'!B13 -> Diseño | E19: =Rendimiento!I$16 | F19: =IF(E19="","","horas") | H19: ='Datos proyecto'!B13 -> Diseño | I19: =Rendimiento!T9 | J19: =IF(I19="","","horas")
A20: ='Datos proyecto'!B14 -> Inspección de diseño | B20: =Rendimiento!R10 | D20: ='Datos proyecto'!B14 -> Inspección de diseño | E20: =Rendimiento!J$16 | F20: =IF(E20="","","horas") | H20: ='Datos proyecto'!B14 -> Inspección de diseño | I20: =Rendimiento!T10 | J20: =IF(I20="","","horas")
A21: ='Datos proyecto'!B15 -> Código | B21: =Rendimiento!R11 -> 0 | D21: ='Datos proyecto'!B15 -> Código | E21: =Rendimiento!K$16 | F21: =IF(E21="","","horas") | H21: ='Datos proyecto'!B15 -> Código | I21: =Rendimiento!T11 -> 0.225 | J21: =IF(I21="","","horas") -> horas
A22: ='Datos proyecto'!B16 -> Revisión de código | B22: =Rendimiento!R12 -> 0.5 | D22: ='Datos proyecto'!B16 -> Revisión de código | E22: =Rendimiento!L$16 -> 0.42 | F22: =IF(E22="","","horas") -> horas | H22: ='Datos proyecto'!B16 -> Revisión de código | I22: =Rendimiento!T12 | J22: =IF(I22="","","horas")
A23: ='Datos proyecto'!B17 -> Pruebas | B23: =Rendimiento!R13 -> 1 | D23: ='Datos proyecto'!B17 -> Pruebas | E23: =Rendimiento!M$16 -> 0.03 | F23: =IF(E23="","","horas") -> horas | H23: ='Datos proyecto'!B17 -> Pruebas | I23: =Rendimiento!T13 | J23: =IF(I23="","","horas")
A27: Defectos tipo | B27: Recuento | C27: Porcentaje
A28: ='Estandar defectos'!A2 -> Documentación | B28: =COUNTIF('Lista defectos'!E$3:E$300,'Informe Calidad'!A28) -> 0 | C28: =B28/$B$5 -> 0
A29: ='Estandar defectos'!A3 -> Sintaxis | B29: =COUNTIF('Lista defectos'!E$3:E$300,'Informe Calidad'!A29) -> 2 | C29: =B29/$B$5 -> 1
A30: ='Estandar defectos'!A4 -> Configuración | B30: =COUNTIF('Lista defectos'!E$3:E$300,'Informe Calidad'!A30) -> 0 | C30: =B30/$B$5 -> 0
A31: ='Estandar defectos'!A5 -> Asignaciones | B31: =COUNTIF('Lista defectos'!E$3:E$300,'Informe Calidad'!A31) -> 0 | C31: =B31/$B$5 -> 0
A32: ='Estandar defectos'!A6 -> Interface | B32: =COUNTIF('Lista defectos'!E$3:E$300,'Informe Calidad'!A32) -> 0 | C32: =B32/$B$5 -> 0
A33: ='Estandar defectos'!A7 -> Comprobación | B33: =COUNTIF('Lista defectos'!E$3:E$300,'Informe Calidad'!A33) -> 0 | C33: =B33/$B$5 -> 0
A34: ='Estandar defectos'!A8 -> Datos | B34: =COUNTIF('Lista defectos'!E$3:E$300,'Informe Calidad'!A34) -> 0 | C34: =B34/$B$5 -> 0
A35: ='Estandar defectos'!A9 -> Funciones | B35: =COUNTIF('Lista defectos'!E$3:E$300,'Informe Calidad'!A35) -> 0 | C35: =B35/$B$5 -> 0
A36: ='Estandar defectos'!A10 -> Estandar | B36: =COUNTIF('Lista defectos'!E$3:E$300,'Informe Calidad'!A36) -> 0 | C36: =B36/$B$5 -> 0
A37: ='Estandar defectos'!A11 -> Entorno | B37: =COUNTIF('Lista defectos'!E$3:E$300,'Informe Calidad'!A37) -> 0 | C37: =B37/$B$5 -> 0
